Workbook
Name ALBERT_LEA_SEED: #REF!
Name PIONEER: #REF!
Name PEAS: MATRIX!$M$3:$M$1003
Name SEED_CORN: MATRIX!$K$3:$K$1003
Name SUNFLOWERS: MATRIX!$A$3:$A$1003
Name KENNEL_SEED_FARMS: #REF!
Name SNAP_BEANS: MATRIX!$L$3:$L$1003
Name ORGANIC_YELLOW: #REF!
Name MAIN: #REF!
Name ORGANIC_SOYBEANS: #REF!
Name Oats: MATRIX!$A$3:$N$1003
Name BLUE_CORN: MATRIX!$I$3:$I$1003
Name SORGHUM: MATRIX!$B$3:$B$1003
Name YELLOW_CORN: MATRIX!$D$3:$D$1003
Name HARTUNG_BROTHERS_SEED: #REF!
Name KWS: #REF!
Name RAINBOW_VALLEY_SEED: #REF!
Name BARLEY: MATRIX!$O$3:$O$1003
Name SENECA_FOODS: #REF!
Name TYPE: MATRIX!$R$4:$R$19
Name WHITE_CORN: MATRIX!$E$3:$E$1003
Name ALFALFA: MATRIX!$G$3:$G$1003
Name DELONGS: #REF!
Name CHAMPAIGN_COUNTY_SEED: #REF!
Name WHEAT: MATRIX!$F$3:$F$1003
Name GREAT_HARVEST_ORGANICS: #REF!
Name LIMA_BEANS: MATRIX!$J$3:$J$1003
Name HYBRID_RYE: MATRIX!$H$3:$H$1003
Name SOYBEANS: MATRIX!$C$3:$C$1003

Sheet SEED INVENTORY
A1: =L15 -> LBS | D1: DELIVERY | K1: delivered
A2: Date | B2: Name | C2: LOT | D2: Ticket NUMBER | E2: Product type | F2: IN/OUT | G2: BRAND | H2: CROP | I2: Variety | K2: Quantity | L2: Unit type | M2: Pack quantity | N2: Pack type | P2: Input | Q2: Input Quantity | R2: Input unit | S2: Notes | T2: Return QUANTITY | U2: TYPE | V2: Notes
A3: 44775 | B3: Randy | D3: B22-12024 | E3: Seed | F3: Incoming | G3: Albert Lea | H3: Barley | I3: SB151 | K3: 15380 | L3: LBS | M3: 320 | N3: Units | S3: Picked up by Randy S truck 2
A4: 44831 | B4: Bob | C4: 22U-44WH | D4: B22-14970 | E4: Seed | F4: Incoming | G4: Albert Lea | H4: Wheat | I4: LCS 3334 | K4: 30000 | L4: LBS | M4: 600 | N4: SOFT TOTE | S4: Picked up by Bob O truck 5
A5: 44831 | B5: Bob | C5: 22U-47WH | D5: B22-14970 | E5: Seed | F5: Incoming | G5: Albert Lea | H5: Wheat | I5: LCS 3334 | K5: 2500 | L5: LBS | M5: 50 | N5: 50lb Paper Bag | S5: Picked up by Bob O truck 5
A6: 44831 | B6: Bob | C6: 9190913 | D6: B22-14970 | E6: Seed | F6: Incoming | G6: Albert Lea | H6: winter camelina | I6: VNS | K6: 250 | L6: LBS | M6: 1 | N6: Units | S6: Picked up by Bob O truck 5
A7: 44831 | B7: Bob | C7: 22U-82AK | D7: B22-14970 | E7: Seed | F7: Incoming | G7: Albert Lea | H7: Rye | I7: Hazlett | K7: 16000 | L7: LBS | M7: 320 | N7: SOFT TOTE | S7: Picked up by Bob O truck 5
A8: 44834 | B8: Bob | C8: TSTS2203 | D8: 99100 | E8: Seed | F8: Incoming | G8: Tracy Seeds | H8: Wheat | I8: TW92-22 | K8: 2400 | L8: LBS | M8: 48 | N8: Bag | S8: Picked up by Bob O -Tracy's
A9: 44834 | B9: Bob | C9: TSTS2203 | D9: 99100 | E9: Seed | F9: Incoming | G9: Tracy Seeds | H9: Wheat | I9: TW92-22 | K9: 22000 | L9: LBS | M9: 440 | N9: Bag | S9: Picked up by Bob O - Tracy's
A10: 44869 | B10: Tim | D10: 122883 | E10: Input | F10: Incoming | K10: 6816 | L10: LBS | P10: 0-0-60 Potash | Q10: 6816 | R10: Lbs
A11: 44869 | B11: Tim | D11: 122883 | E11: input | F11: Incoming | K11: 4544 | L11: LBS | P11: 18-46-0 DAP | Q11: 4544 | R11: Lbs
A12: 44880 | B12: Bob | D12: 6550907 | E12: Input | F12: Incoming | K12: 55700 | L12: LBS | M12: 55700 | N12: Bulk | P12: 0-0-50-17s | Q12: 55700 | R12: Lbs | S12: Picked up by Bob @ J&L Fert Morris IL
A13: 44964 | B13: Jason | C13: 4803 | D13: 1007735 | E13: Input | F13: Incoming | K13: 50000 | L13: LBS | M13: 50000 | N13: Bulk | P13: S04 30% | Q13: 50000 | R13: Lbs | S13: Picked up by Jason, Milledgville, IL
A14: 44970 | B14: Jason | C14: 4807 | D14: 1007735 | E14: Input | F14: Incoming | K14: 50000 | L14: LBS | M14: 50000 | N14: Bulk | P14: S04 30% | Q14: 50000 | R14: Lbs | S14: Picked up by Jason, Milledgville, IL
A15: 44967 | B15: Robert | C15: 4805 | D15: 1007735 | E15: Input | F15: Incoming | K15: 50000 | L15: LBS | M15: 50000 | N15: Bulk | P15: S04 30% | Q15: 50000 | R15: Lbs | S15: Picked up by Robert, Milledgville, IL
A16: 44978 | B16: jason | C16: 4810 | D16: 0 | E16: Input | F16: Incoming | K16: 25000 | L16: LBS | M16: 25000 | N16: Bulk | P16: S04 30% | Q16: 25000 | R16: Lbs | S16: Picked up by Jason, Milledgville, IL
A17: 44986 | D17: 3653 | E17: Input | F17: Incoming | K17: 18 | L17: Units | M17: 18 | N17: 2.5 gal JUG | P17: Eco Tec | Q17: 18 | R17: 2.5 gal JUG | S17: dropped off by AgriEnergy
A18: 44986 | D18: 3653 | E18: Input | F18: Incoming | K18: 3 | L18: Units | M18: 3 | N18: 2.5 gal JUG | P18: BioRepel | Q18: 3 | R18: 2.5 gal JUG | S18: dropped off by AgriEnergy
A19: 44988 | D19: 3652 | E19: Input | F19: Incoming | K19: 4 | L19: Box | M19: 6 | N19: Bag | P19: Exceed Soy Inoculant (30 Unit) | Q19: 24 | R19: Bag | S19: dropped off by AgriEnergy
A20: 45009 | B20: Gary | D20: 1012222 | E20: Input | F20: Incoming | K20: 26 | L20: Box | M20: 52 | N20: 2.5 gal JUG | P20: Batallion LFC (2x2.5 Gal) | Q20: 130 | R20: Gallons
A21: 45013 | B21: Gary | C21: 5787001 | E21: Seed | F21: Incoming | G21: Pioneer | H21: Yellow_Corn | I21: P0035 | K21: 6 | L21: Bag
A22: 45013 | B22: Gary | C22: 5489995P | E22: Seed | F22: Incoming | G22: Pioneer | H22: Yellow_Corn | I22: P0075 | K22: 50 | L22: Units | M22: 1 | N22: PROBOX
A23: 45013 | B23: Gary | C23: 5420613P | E23: Seed | F23: Incoming | G23: Pioneer | H23: Yellow_Corn | I23: P0057 | K23: 100 | L23: Units | M23: 2 | N23: Units in PROBOX
A24: 45013 | B24: Gary | C24: 5420656P | E24: Seed | F24: Incoming | G24: Pioneer | H24: Yellow_Corn | I24: P0075 | K24: 50 | L24: Units | M24: 1 | N24: Units in PROBOX
A25: 45013 | B25: Gary | C25: 5830118P | E25: Seed | F25: Incoming | G25: Pioneer | H25: Yellow_Corn | I25: P0075 | K25: 150 | L25: Units | M25: 3 | N25: Units in PROBOX
A26: 45013 | B26: Gary | C26: 5525885 | E26: Seed | F26: Incoming | G26: Pioneer | H26: Yellow_Corn | I26: P0157 | K26: 11 | L26: bag | N26: 80k Paper bag
A27: 45013 | B27: Gary | C27: 5574167 | E27: Seed | F27: Incoming | G27: Pioneer | H27: Yellow_Corn | I27: P0157 | K27: 17 | L27: Bag | N27: 80k Paper bag
A28: 45013 | B28: Gary | C28: 5707984P | E28: Seed | F28: Incoming | G28: Pioneer | H28: Yellow_Corn | I28: P0720 | K28: 100 | L28: Bag | M28: 2 | N28: Units in PROBOX
A29: 45013 | B29: Gary | C29: 5773155P | E29: Seed | F29: Incoming | G29: Pioneer | H29: Yellow_Corn | I29: P0924 | K29: 120 | L29: Units | M29: 3 | N29: Units in PROBOX
A30: 45013 | B30: Gary | C30: 5704216 | E30: Seed | F30: Incoming | G30: Pioneer | H30: Sunflowers | I30: P63ME80 | K30: 30 | L30: Bag | M30: 30 | N30: 50lb Paper Bag
A31: 45013 | B31: Gary | C31: 5814581 | E31: Seed | F31: Incoming | G31: Pioneer | H31: sorghum | I31: 88P71 | K31: 30 | L31: Bag | M31: 30 | N31: 50lb Paper Bag
A32: 45013 | B32: Gary | C32: 5814472 | E32: Seed | F32: Incoming | G32: Pioneer | H32: Sorghum | I32: 88P71 | K32: 30 | L32: bag
A33: 45023 | B33: Tim | D33: 1771 | E33: Input | F33: Incoming | K33: 3400 | L33: GAL | P33: CX-1 Pro | Q33: 3400 | R33: Gallons | S33: delivered by purple cow
A34: 45030 | B34: Tim | D34: 1012440 | E34: Seed | F34: Incoming | G34: Pioneer | H34: Soybeans | I34: P21A20 | K34: 350 | L34: Bag | M34: 4 | N34: PROBOX
A35: 45023 | C35: 14286 | D35: 12408 | E35: Input | F35: Incoming | K35: 25000 | L35: LBS | P35: 46-0-0 Urea | Q35: 25000 | R35: Lbs | S35: Picked up in Clinton
A36: 45023 | C36: 12497 | D36: 12409 | E36: Input | F36: Incoming | K36: 24.842 | L36: Tons | P36: 46-0-0 Urea | Q36: 25000 | R36: Lbs | S36: Picked up in Clinton
A37: 45029 | C37: 124253 | D37: 10012213 | E37: Input | F37: Incoming | K37: 24.842 | L37: Tons | M37: 25 | N37: Units | P37: 10-34-0 | Q37: 52040 | R37: Lbs | S37: Delong Blend Ticket # 124253
A38: 45029 | C38: 124253 | D38: 10012213 | E38: Input | F38: Incoming | K38: 212.32 | L38: GAL | M38: 212.32 | P38: 13-0-0-15 Zn (Gal) | Q38: 212.32 | R38: Gallons | S38: Delong Blend Ticket # 124253
A39: 45035 | B39: Tim | D39: 2365579 | E39: Input | F39: Incoming | K39: 250 | L39: GAL | M39: 250 | N39: 15 Gal Box | P39: Accompish Max | Q39: 250 | R39: Gallons | S39: Delivered by Nutrien Ag Sys
A40: 45035 | B40: Tim | D40: 23655791 | E40: Input | F40: Incoming | K40: 10 | L40: GAL | M40: 4 | N40: 2.5 gal JUG | P40: Homeplate | Q40: 10 | R40: Gallons | S40: Delivered by Nutrien Ag Sys
...

Sheet Sheet10

Sheet INPUT COMPARISON
A4: =IFERROR(__xludf.DUMMYFUNCTION("IMPORTRANGE(""https://docs.google.com/spreadsheets/d/1ROIDByG8JQ9QnTav5kMbqjv_otDakkYL7H10iPWcU48/edit#gid=259472266"",""Inputs!A1:A"")"),"FERTILLIZER AND CHEMICAL") -> FERTILLIZER AND CHEMICAL | D4: =IFERROR(__xludf.DUMMYFUNCTION("IMPORTRANGE(""https://docs.google.com/spreadsheets/d/1i_N2vQg61P41rmjGCBpk2fCS6k6Bg53Vw5VyEESSCdg/edit#gid=259472266"",""Inputs!z1:AA"")"),"")
A5: =IFERROR(__xludf.DUMMYFUNCTION("""COMPUTED_VALUE"""),"Product") -> Product | D5: =IFERROR(__xludf.DUMMYFUNCTION("""COMPUTED_VALUE"""),"TOTAL PROJECTED UNITS") -> TOTAL PROJECTED UNITS | E5: =IFERROR(__xludf.DUMMYFUNCTION("""COMPUTED_VALUE"""),"UNIT") -> UNIT | F5: Total Units Ordered | H5: Total Units Delivered | J5: Total Units Returned | L5: Balance
A6: =IFERROR(__xludf.DUMMYFUNCTION("""COMPUTED_VALUE"""),"0-0-60 Potash") -> 0-0-60 Potash | D6: =IFERROR(__xludf.DUMMYFUNCTION("""COMPUTED_VALUE"""),264021.61) -> 264021.61 | E6: =IFERROR(__xludf.DUMMYFUNCTION("""COMPUTED_VALUE"""),"Lbs") -> Lbs | H6: =sumif('SEED INVENTORY'!$P$46:$P1000,A6,'SEED INVENTORY'!$Q$46:$Q1000) -> 0 | I6: =vlookup(A6,'SEED INVENTORY'!$P$46:$R1000,3,False) -> #N/A | J6: =sumif('SEED INVENTORY'!$T$46:$T1000,A6,'SEED INVENTORY'!$U$46:$U1000) -> 0
A7: =IFERROR(__xludf.DUMMYFUNCTION("""COMPUTED_VALUE"""),"10-34-0") -> 10-34-0 | D7: =IFERROR(__xludf.DUMMYFUNCTION("""COMPUTED_VALUE"""),9899.5) -> 9899.5 | E7: =IFERROR(__xludf.DUMMYFUNCTION("""COMPUTED_VALUE"""),"Gal") -> Gal | H7: =sumif('SEED INVENTORY'!$P$46:$P1000,A7,'SEED INVENTORY'!$Q$46:$Q1000) -> 28940 | I7: =vlookup(A7,'SEED INVENTORY'!$P$46:$R1000,3,False) -> Lbs | J7: =sumif('SEED INVENTORY'!$T$46:$T1000,A7,'SEED INVENTORY'!$U$46:$U1000) -> 0
A8: =IFERROR(__xludf.DUMMYFUNCTION("""COMPUTED_VALUE"""),"12-0-0-26 Amm Thio") -> 12-0-0-26 Amm Thio | D8: =IFERROR(__xludf.DUMMYFUNCTION("""COMPUTED_VALUE"""),109737.1812) -> 109737.18 | E8: =IFERROR(__xludf.DUMMYFUNCTION("""COMPUTED_VALUE"""),"Lbs") -> Lbs | H8: =sumif('SEED INVENTORY'!$P$46:$P1000,A8,'SEED INVENTORY'!$Q$46:$Q1000) -> 0 | I8: =vlookup(A8,'SEED INVENTORY'!$P$46:$R1000,3,False) -> #N/A | J8: =sumif('SEED INVENTORY'!$T$46:$T1000,A8,'SEED INVENTORY'!$U$46:$U1000) -> 0
A9: =IFERROR(__xludf.DUMMYFUNCTION("""COMPUTED_VALUE"""),"13-0-0-15 Zn (Gal)") -> 13-0-0-15 Zn (Gal) | D9: =IFERROR(__xludf.DUMMYFUNCTION("""COMPUTED_VALUE"""),0.0) -> 0 | E9: =IFERROR(__xludf.DUMMYFUNCTION("""COMPUTED_VALUE"""),"Gal") -> Gal | H9: =sumif('SEED INVENTORY'!$P$46:$P1000,A9,'SEED INVENTORY'!$Q$46:$Q1000) -> 0 | I9: =vlookup(A9,'SEED INVENTORY'!$P$46:$R1000,3,False) -> #N/A | J9: =sumif('SEED INVENTORY'!$T$46:$T1000,A9,'SEED INVENTORY'!$U$46:$U1000) -> 0
A10: =IFERROR(__xludf.DUMMYFUNCTION("""COMPUTED_VALUE"""),"18-46-0 DAP") -> 18-46-0 DAP | D10: =IFERROR(__xludf.DUMMYFUNCTION("""COMPUTED_VALUE"""),265363.44500000007) -> 265363.45 | E10: =IFERROR(__xludf.DUMMYFUNCTION("""COMPUTED_VALUE"""),"Lbs") -> Lbs | H10: =sumif('SEED INVENTORY'!$P$46:$P1000,A10,'SEED INVENTORY'!$Q$46:$Q1000) -> 0 | I10: =vlookup(A10,'SEED INVENTORY'!$P$46:$R1000,3,False) -> #N/A | J10: =sumif('SEED INVENTORY'!$T$46:$T1000,A10,'SEED INVENTORY'!$U$46:$U1000) -> 0
A11: =IFERROR(__xludf.DUMMYFUNCTION("""COMPUTED_VALUE"""),"21-0-0-24s AMS Granular") -> 21-0-0-24s AMS Granular | D11: =IFERROR(__xludf.DUMMYFUNCTION("""COMPUTED_VALUE"""),42163.05) -> 42163.05 | E11: =IFERROR(__xludf.DUMMYFUNCTION("""COMPUTED_VALUE"""),"Lbs") -> Lbs | H11: =sumif('SEED INVENTORY'!$P$46:$P1000,A11,'SEED INVENTORY'!$Q$46:$Q1000) -> 0 | I11: =vlookup(A11,'SEED INVENTORY'!$P$46:$R1000,3,False) -> #N/A | J11: =sumif('SEED INVENTORY'!$T$46:$T1000,A11,'SEED INVENTORY'!$U$46:$U1000) -> 0
A12: =IFERROR(__xludf.DUMMYFUNCTION("""COMPUTED_VALUE"""),"28% Nitrogen") -> 28% Nitrogen | D12: =IFERROR(__xludf.DUMMYFUNCTION("""COMPUTED_VALUE"""),6806.5) -> 6806.5 | E12: =IFERROR(__xludf.DUMMYFUNCTION("""COMPUTED_VALUE"""),"Gal") -> Gal | H12: =sumif('SEED INVENTORY'!$P$46:$P1000,A12,'SEED INVENTORY'!$Q$46:$Q1000) -> 0 | I12: =vlookup(A12,'SEED INVENTORY'!$P$46:$R1000,3,False) -> #N/A | J12: =sumif('SEED INVENTORY'!$T$46:$T1000,A12,'SEED INVENTORY'!$U$46:$U1000) -> 0
A13: =IFERROR(__xludf.DUMMYFUNCTION("""COMPUTED_VALUE"""),"32% Nitrogen") -> 32% Nitrogen | D13: =IFERROR(__xludf.DUMMYFUNCTION("""COMPUTED_VALUE"""),4505.900000000001) -> 4505.9 | E13: =IFERROR(__xludf.DUMMYFUNCTION("""COMPUTED_VALUE"""),"Gal") -> Gal | H13: =sumif('SEED INVENTORY'!$P$46:$P1000,A13,'SEED INVENTORY'!$Q$46:$Q1000) -> 0 | I13: =vlookup(A13,'SEED INVENTORY'!$P$46:$R1000,3,False) | J13: =sumif('SEED INVENTORY'!$T$46:$T1000,A13,'SEED INVENTORY'!$U$46:$U1000) -> 0
A14: =IFERROR(__xludf.DUMMYFUNCTION("""COMPUTED_VALUE"""),"46-0-0 Urea") -> 46-0-0 Urea | D14: =IFERROR(__xludf.DUMMYFUNCTION("""COMPUTED_VALUE"""),754482.5) -> 754482.5 | E14: =IFERROR(__xludf.DUMMYFUNCTION("""COMPUTED_VALUE"""),"Lbs") -> Lbs | H14: =sumif('SEED INVENTORY'!$P$46:$P1000,A14,'SEED INVENTORY'!$Q$46:$Q1000) -> 56320 | I14: =vlookup(A14,'SEED INVENTORY'!$P$46:$R1000,3,False) -> Lbs | J14: =sumif('SEED INVENTORY'!$T$46:$T1000,A14,'SEED INVENTORY'!$U$46:$U1000) -> 0
A15: =IFERROR(__xludf.DUMMYFUNCTION("""COMPUTED_VALUE"""),"Accuquest WM (2x2.5 Gal)") -> Accuquest WM (2x2.5 Gal) | D15: =IFERROR(__xludf.DUMMYFUNCTION("""COMPUTED_VALUE"""),138.62) -> 138.62 | E15: =IFERROR(__xludf.DUMMYFUNCTION("""COMPUTED_VALUE"""),"Pts") -> Pts | H15: =sumif('SEED INVENTORY'!$P$46:$P1000,A15,'SEED INVENTORY'!$Q$46:$Q1000) -> 0 | I15: =vlookup(A15,'SEED INVENTORY'!$P$46:$R1000,3,False) -> #N/A | J15: =sumif('SEED INVENTORY'!$T$46:$T1000,A15,'SEED INVENTORY'!$U$46:$U1000) -> 0
A16: =IFERROR(__xludf.DUMMYFUNCTION("""COMPUTED_VALUE"""),"Application - Burndown") -> Application - Burndown | D16: =IFERROR(__xludf.DUMMYFUNCTION("""COMPUTED_VALUE"""),55.68) -> 55.68 | E16: =IFERROR(__xludf.DUMMYFUNCTION("""COMPUTED_VALUE"""),"Acre") -> Acre | H16: =sumif('SEED INVENTORY'!$P$46:$P1000,A16,'SEED INVENTORY'!$Q$46:$Q1000) -> 0 | I16: =vlookup(A16,'SEED INVENTORY'!$P$46:$R1000,3,False) -> #N/A | J16: =sumif('SEED INVENTORY'!$T$46:$T1000,A16,'SEED INVENTORY'!$U$46:$U1000) -> 0
A17: =IFERROR(__xludf.DUMMYFUNCTION("""COMPUTED_VALUE"""),"Application - Liquid Ppi") -> Application - Liquid Ppi | D17: =IFERROR(__xludf.DUMMYFUNCTION("""COMPUTED_VALUE"""),286.4) -> 286.4 | E17: =IFERROR(__xludf.DUMMYFUNCTION("""COMPUTED_VALUE"""),"Acre") -> Acre | H17: =sumif('SEED INVENTORY'!$P$46:$P1000,A17,'SEED INVENTORY'!$Q$46:$Q1000) -> 0 | I17: =vlookup(A17,'SEED INVENTORY'!$P$46:$R1000,3,False) -> #N/A | J17: =sumif('SEED INVENTORY'!$T$46:$T1000,A17,'SEED INVENTORY'!$U$46:$U1000) -> 0
A18: =IFERROR(__xludf.DUMMYFUNCTION("""COMPUTED_VALUE"""),"Application - Liquid Pre") -> Application - Liquid Pre | D18: =IFERROR(__xludf.DUMMYFUNCTION("""COMPUTED_VALUE"""),2490.9395) -> 2490.9395 | E18: =IFERROR(__xludf.DUMMYFUNCTION("""COMPUTED_VALUE"""),"Acre") -> Acre | H18: =sumif('SEED INVENTORY'!$P$46:$P1000,A18,'SEED INVENTORY'!$Q$46:$Q1000) -> 0 | I18: =vlookup(A18,'SEED INVENTORY'!$P$46:$R1000,3,False) -> #N/A | J18: =sumif('SEED INVENTORY'!$T$46:$T1000,A18,'SEED INVENTORY'!$U$46:$U1000) -> 0
A19: =IFERROR(__xludf.DUMMYFUNCTION("""COMPUTED_VALUE"""),"Application - Post") -> Application - Post | D19: =IFERROR(__xludf.DUMMYFUNCTION("""COMPUTED_VALUE"""),3342.4881920000003) -> 3342.4882 | E19: =IFERROR(__xludf.DUMMYFUNCTION("""COMPUTED_VALUE"""),"Acre") -> Acre | H19: =sumif('SEED INVENTORY'!$P$46:$P1000,A19,'SEED INVENTORY'!$Q$46:$Q1000) -> 0 | I19: =vlookup(A19,'SEED INVENTORY'!$P$46:$R1000,3,False) -> #N/A | J19: =sumif('SEED INVENTORY'!$T$46:$T1000,A19,'SEED INVENTORY'!$U$46:$U1000) -> 0
A20: =IFERROR(__xludf.DUMMYFUNCTION("""COMPUTED_VALUE"""),"Application - Spinner") -> Application - Spinner | D20: =IFERROR(__xludf.DUMMYFUNCTION("""COMPUTED_VALUE"""),0.0) -> 0 | E20: =IFERROR(__xludf.DUMMYFUNCTION("""COMPUTED_VALUE"""),"Acre") -> Acre | H20: =sumif('SEED INVENTORY'!$P$46:$P1000,A20,'SEED INVENTORY'!$Q$46:$Q1000) -> 0 | I20: =vlookup(A20,'SEED INVENTORY'!$P$46:$R1000,3,False) -> #N/A | J20: =sumif('SEED INVENTORY'!$T$46:$T1000,A20,'SEED INVENTORY'!$U$46:$U1000) -> 0
A21: =IFERROR(__xludf.DUMMYFUNCTION("""COMPUTED_VALUE"""),"Application - Tons Of Lime Applied") -> Application - Tons Of Lime Applied | D21: =IFERROR(__xludf.DUMMYFUNCTION("""COMPUTED_VALUE"""),153.0) -> 153 | E21: =IFERROR(__xludf.DUMMYFUNCTION("""COMPUTED_VALUE"""),"Tons") -> Tons | H21: =sumif('SEED INVENTORY'!$P$46:$P1000,A21,'SEED INVENTORY'!$Q$46:$Q1000) -> 0 | I21: =vlookup(A21,'SEED INVENTORY'!$P$46:$R1000,3,False) -> #N/A | J21: =sumif('SEED INVENTORY'!$T$46:$T1000,A21,'SEED INVENTORY'!$U$46:$U1000) -> 0
A22: =IFERROR(__xludf.DUMMYFUNCTION("""COMPUTED_VALUE"""),"Application - Vrt") -> Application - Vrt | D22: =IFERROR(__xludf.DUMMYFUNCTION("""COMPUTED_VALUE"""),102.0) -> 102 | E22: =IFERROR(__xludf.DUMMYFUNCTION("""COMPUTED_VALUE"""),"Acre") -> Acre | H22: =sumif('SEED INVENTORY'!$P$46:$P1000,A22,'SEED INVENTORY'!$Q$46:$Q1000) -> 0 | I22: =vlookup(A22,'SEED INVENTORY'!$P$46:$R1000,3,False) -> #N/A | J22: =sumif('SEED INVENTORY'!$T$46:$T1000,A22,'SEED INVENTORY'!$U$46:$U1000) -> 0
A23: =IFERROR(__xludf.DUMMYFUNCTION("""COMPUTED_VALUE"""),"Application - VRT Spinner") -> Application - VRT Spinner | D23: =IFERROR(__xludf.DUMMYFUNCTION("""COMPUTED_VALUE"""),0.0) -> 0 | E23: =IFERROR(__xludf.DUMMYFUNCTION("""COMPUTED_VALUE"""),"Acre") -> Acre | H23: =sumif('SEED INVENTORY'!$P$46:$P1000,A23,'SEED INVENTORY'!$Q$46:$Q1000) -> 0 | I23: =vlookup(A23,'SEED INVENTORY'!$P$46:$R1000,3,False) -> #N/A | J23: =sumif('SEED INVENTORY'!$T$46:$T1000,A23,'SEED INVENTORY'!$U$46:$U1000) -> 0
A24: =IFERROR(__xludf.DUMMYFUNCTION("""COMPUTED_VALUE"""),"Armezon (6x32 Oz)") -> Armezon (6x32 Oz) | D24: =IFERROR(__xludf.DUMMYFUNCTION("""COMPUTED_VALUE"""),1025.4823999999999) -> 1025.4824 | E24: =IFERROR(__xludf.DUMMYFUNCTION("""COMPUTED_VALUE"""),"OZ") -> OZ | H24: =sumif('SEED INVENTORY'!$P$46:$P1000,A24,'SEED INVENTORY'!$Q$46:$Q1000) -> 0 | I24: =vlookup(A24,'SEED INVENTORY'!$P$46:$R1000,3,False) -> #N/A | J24: =sumif('SEED INVENTORY'!$T$46:$T1000,A24,'SEED INVENTORY'!$U$46:$U1000) -> 0
A25: =IFERROR(__xludf.DUMMYFUNCTION("""COMPUTED_VALUE"""),"Accent Q (18 oz)") -> Accent Q (18 oz) | D25: =IFERROR(__xludf.DUMMYFUNCTION("""COMPUTED_VALUE"""),298.3954) -> 298.3954 | E25: =IFERROR(__xludf.DUMMYFUNCTION("""COMPUTED_VALUE"""),"OZ") -> OZ | H25: =sumif('SEED INVENTORY'!$P$46:$P1000,A25,'SEED INVENTORY'!$Q$46:$Q1000) -> 0 | I25: =vlookup(A25,'SEED INVENTORY'!$P$46:$R1000,3,False) -> #N/A | J25: =sumif('SEED INVENTORY'!$T$46:$T1000,A25,'SEED INVENTORY'!$U$46:$U1000) -> 0
A26: =IFERROR(__xludf.DUMMYFUNCTION("""COMPUTED_VALUE"""),"Atrazine 90DF (25 lb)") -> Atrazine 90DF (25 lb) | D26: =IFERROR(__xludf.DUMMYFUNCTION("""COMPUTED_VALUE"""),35.669999999999995) -> 35.67 | E26: =IFERROR(__xludf.DUMMYFUNCTION("""COMPUTED_VALUE"""),"Lbs") -> Lbs | H26: =sumif('SEED INVENTORY'!$P$46:$P1000,A26,'SEED INVENTORY'!$Q$46:$Q1000) -> 0 | I26: =vlookup(A26,'SEED INVENTORY'!$P$46:$R1000,3,False) -> #N/A | J26: =sumif('SEED INVENTORY'!$T$46:$T1000,A26,'SEED INVENTORY'!$U$46:$U1000) -> 0
A27: =IFERROR(__xludf.DUMMYFUNCTION("""COMPUTED_VALUE"""),"Authority First DF (2x10 Lb)") -> Authority First DF (2x10 Lb) | D27: =IFERROR(__xludf.DUMMYFUNCTION("""COMPUTED_VALUE"""),0.0) -> 0 | E27: =IFERROR(__xludf.DUMMYFUNCTION("""COMPUTED_VALUE"""),"OZ") -> OZ | H27: =sumif('SEED INVENTORY'!$P$46:$P1000,A27,'SEED INVENTORY'!$Q$46:$Q1000) -> 0 | I27: =vlookup(A27,'SEED INVENTORY'!$P$46:$R1000,3,False) -> #N/A | J27: =sumif('SEED INVENTORY'!$T$46:$T1000,A27,'SEED INVENTORY'!$U$46:$U1000) -> 0
A28: =IFERROR(__xludf.DUMMYFUNCTION("""COMPUTED_VALUE"""),"Basagran (2x2.5 Gal)") -> Basagran (2x2.5 Gal) | D28: =IFERROR(__xludf.DUMMYFUNCTION("""COMPUTED_VALUE"""),8975.35) -> 8975.35 | E28: =IFERROR(__xludf.DUMMYFUNCTION("""COMPUTED_VALUE"""),"OZ") -> OZ | H28: =sumif('SEED INVENTORY'!$P$46:$P1000,A28,'SEED INVENTORY'!$Q$46:$Q1000) -> 0 | I28: =vlookup(A28,'SEED INVENTORY'!$P$46:$R1000,3,False) -> #N/A | J28: =sumif('SEED INVENTORY'!$T$46:$T1000,A28,'SEED INVENTORY'!$U$46:$U1000) -> 0
A29: =IFERROR(__xludf.DUMMYFUNCTION("""COMPUTED_VALUE"""),"Blazer 94x1 Gal)") -> Blazer 94x1 Gal) | D29: =IFERROR(__xludf.DUMMYFUNCTION("""COMPUTED_VALUE"""),"#DIV/0!") -> #DIV/0! | E29: =IFERROR(__xludf.DUMMYFUNCTION("""COMPUTED_VALUE"""),"Tons") -> Tons | H29: =sumif('SEED INVENTORY'!$P$46:$P1000,A29,'SEED INVENTORY'!$Q$46:$Q1000) -> 0 | I29: =vlookup(A29,'SEED INVENTORY'!$P$46:$R1000,3,False) -> #N/A | J29: =sumif('SEED INVENTORY'!$T$46:$T1000,A29,'SEED INVENTORY'!$U$46:$U1000) -> 0
A30: =IFERROR(__xludf.DUMMYFUNCTION("""COMPUTED_VALUE"""),"Butyrac 200 (2x2.5 Gal)") -> Butyrac 200 (2x2.5 Gal) | D30: =IFERROR(__xludf.DUMMYFUNCTION("""COMPUTED_VALUE"""),"#DIV/0!") -> #DIV/0! | E30: =IFERROR(__xludf.DUMMYFUNCTION("""COMPUTED_VALUE"""),"Tons") -> Tons | H30: =sumif('SEED INVENTORY'!$P$46:$P1000,A30,'SEED INVENTORY'!$Q$46:$Q1000) -> 0 | I30: =vlookup(A30,'SEED INVENTORY'!$P$46:$R1000,3,False) -> #N/A | J30: =sumif('SEED INVENTORY'!$T$46:$T1000,A30,'SEED INVENTORY'!$U$46:$U1000) -> 0
A31: =IFERROR(__xludf.DUMMYFUNCTION("""COMPUTED_VALUE"""),"Capture LFR (2x2.5 Gal)") -> Capture LFR (2x2.5 Gal) | D31: =IFERROR(__xludf.DUMMYFUNCTION("""COMPUTED_VALUE"""),18308.420000000002) -> 18308.42 | E31: =IFERROR(__xludf.DUMMYFUNCTION("""COMPUTED_VALUE"""),"OZ") -> OZ | H31: =sumif('SEED INVENTORY'!$P$46:$P1000,A31,'SEED INVENTORY'!$Q$46:$Q1000) -> 0 | I31: =vlookup(A31,'SEED INVENTORY'!$P$46:$R1000,3,False) -> #N/A | J31: =sumif('SEED INVENTORY'!$T$46:$T1000,A31,'SEED INVENTORY'!$U$46:$U1000) -> 0
A32: =IFERROR(__xludf.DUMMYFUNCTION("""COMPUTED_VALUE"""),"Ceridian 2 EC (2x2.5 Gal)") -> Ceridian 2 EC (2x2.5 Gal) | D32: =IFERROR(__xludf.DUMMYFUNCTION("""COMPUTED_VALUE"""),2592.52) -> 2592.52 | E32: =IFERROR(__xludf.DUMMYFUNCTION("""COMPUTED_VALUE"""),"OZ") -> OZ | H32: =sumif('SEED INVENTORY'!$P$46:$P1000,A32,'SEED INVENTORY'!$Q$46:$Q1000) -> 0 | I32: =vlookup(A32,'SEED INVENTORY'!$P$46:$R1000,3,False) -> #N/A | J32: =sumif('SEED INVENTORY'!$T$46:$T1000,A32,'SEED INVENTORY'!$U$46:$U1000) -> 0
A33: =IFERROR(__xludf.DUMMYFUNCTION("""COMPUTED_VALUE"""),"Clarity (2x2.5 Gal)") -> Clarity (2x2.5 Gal) | D33: =IFERROR(__xludf.DUMMYFUNCTION("""COMPUTED_VALUE"""),3585.6860799999995) -> 3585.6861 | E33: =IFERROR(__xludf.DUMMYFUNCTION("""COMPUTED_VALUE"""),"OZ") -> OZ | H33: =sumif('SEED INVENTORY'!$P$46:$P1000,A33,'SEED INVENTORY'!$Q$46:$Q1000) -> 0 | I33: =vlookup(A33,'SEED INVENTORY'!$P$46:$R1000,3,False) -> #N/A | J33: =sumif('SEED INVENTORY'!$T$46:$T1000,A33,'SEED INVENTORY'!$U$46:$U1000) -> 0
A34: =IFERROR(__xludf.DUMMYFUNCTION("""COMPUTED_VALUE"""),"Crop Oil (2x2.5 Gal)") -> Crop Oil (2x2.5 Gal) | D34: =IFERROR(__xludf.DUMMYFUNCTION("""COMPUTED_VALUE"""),8245.926) -> 8245.926 | E34: =IFERROR(__xludf.DUMMYFUNCTION("""COMPUTED_VALUE"""),"OZ") -> OZ | H34: =sumif('SEED INVENTORY'!$P$46:$P1000,A34,'SEED INVENTORY'!$Q$46:$Q1000) -> 0 | I34: =vlookup(A34,'SEED INVENTORY'!$P$46:$R1000,3,False) -> #N/A | J34: =sumif('SEED INVENTORY'!$T$46:$T1000,A34,'SEED INVENTORY'!$U$46:$U1000) -> 0
A35: =IFERROR(__xludf.DUMMYFUNCTION("""COMPUTED_VALUE"""),"Cobra (2x2.5 Gal)") -> Cobra (2x2.5 Gal) | D35: =IFERROR(__xludf.DUMMYFUNCTION("""COMPUTED_VALUE"""),3332.2599999999998) -> 3332.26 | E35: =IFERROR(__xludf.DUMMYFUNCTION("""COMPUTED_VALUE"""),"OZ") -> OZ | H35: =sumif('SEED INVENTORY'!$P$46:$P1000,A35,'SEED INVENTORY'!$Q$46:$Q1000) -> 0 | I35: =vlookup(A35,'SEED INVENTORY'!$P$46:$R1000,3,False) -> #N/A | J35: =sumif('SEED INVENTORY'!$T$46:$T1000,A35,'SEED INVENTORY'!$U$46:$U1000) -> 0
A36: =IFERROR(__xludf.DUMMYFUNCTION("""COMPUTED_VALUE"""),"Distinct (2x7.5 Lb)") -> Distinct (2x7.5 Lb) | D36: =IFERROR(__xludf.DUMMYFUNCTION("""COMPUTED_VALUE"""),0.0) -> 0 | E36: =IFERROR(__xludf.DUMMYFUNCTION("""COMPUTED_VALUE"""),"Lbs") -> Lbs | H36: =sumif('SEED INVENTORY'!$P$46:$P1000,A36,'SEED INVENTORY'!$Q$46:$Q1000) -> 0 | I36: =vlookup(A36,'SEED INVENTORY'!$P$46:$R1000,3,False) -> #N/A | J36: =sumif('SEED INVENTORY'!$T$46:$T1000,A36,'SEED INVENTORY'!$U$46:$U1000) -> 0
A37: =IFERROR(__xludf.DUMMYFUNCTION("""COMPUTED_VALUE"""),"Durango DMA (Bulk)") -> Durango DMA (Bulk) | D37: =IFERROR(__xludf.DUMMYFUNCTION("""COMPUTED_VALUE"""),7926.33) -> 7926.33 | E37: =IFERROR(__xludf.DUMMYFUNCTION("""COMPUTED_VALUE"""),"OZ") -> OZ | H37: =sumif('SEED INVENTORY'!$P$46:$P1000,A37,'SEED INVENTORY'!$Q$46:$Q1000) -> 0 | I37: =vlookup(A37,'SEED INVENTORY'!$P$46:$R1000,3,False) -> #N/A | J37: =sumif('SEED INVENTORY'!$T$46:$T1000,A37,'SEED INVENTORY'!$U$46:$U1000) -> 0
A38: =IFERROR(__xludf.DUMMYFUNCTION("""COMPUTED_VALUE"""),"Durango DMA (2X2.5 Gal)") -> Durango DMA (2X2.5 Gal) | D38: =IFERROR(__xludf.DUMMYFUNCTION("""COMPUTED_VALUE"""),7447.98) -> 7447.98 | E38: =IFERROR(__xludf.DUMMYFUNCTION("""COMPUTED_VALUE"""),"OZ") -> OZ | H38: =sumif('SEED INVENTORY'!$P$46:$P1000,A38,'SEED INVENTORY'!$Q$46:$Q1000) -> 0 | I38: =vlookup(A38,'SEED INVENTORY'!$P$46:$R1000,3,False) -> #N/A | J38: =sumif('SEED INVENTORY'!$T$46:$T1000,A38,'SEED INVENTORY'!$U$46:$U1000) -> 0
A39: =IFERROR(__xludf.DUMMYFUNCTION("""COMPUTED_VALUE"""),"Ester 2,4-D LV (2x2.5 Gal)") -> Ester 2,4-D LV (2x2.5 Gal) | D39: =IFERROR(__xludf.DUMMYFUNCTION("""COMPUTED_VALUE"""),"#DIV/0!") -> #DIV/0! | E39: =IFERROR(__xludf.DUMMYFUNCTION("""COMPUTED_VALUE"""),"Tons") -> Tons | H39: =sumif('SEED INVENTORY'!$P$46:$P1000,A39,'SEED INVENTORY'!$Q$46:$Q1000) -> 0 | I39: =vlookup(A39,'SEED INVENTORY'!$P$46:$R1000,3,False) -> #N/A | J39: =sumif('SEED INVENTORY'!$T$46:$T1000,A39,'SEED INVENTORY'!$U$46:$U1000) -> 0
A40: =IFERROR(__xludf.DUMMYFUNCTION("""COMPUTED_VALUE"""),"Exceed Soy Inoculant (30 Unit)") -> Exceed Soy Inoculant (30 Unit) | D40: =IFERROR(__xludf.DUMMYFUNCTION("""COMPUTED_VALUE"""),0.0) -> 0 | E40: =IFERROR(__xludf.DUMMYFUNCTION("""COMPUTED_VALUE"""),"UNIT") -> UNIT | H40: =sumif('SEED INVENTORY'!$P$46:$P1000,A40,'SEED INVENTORY'!$Q$46:$Q1000) -> 0 | I40: =vlookup(A40,'SEED INVENTORY'!$P$46:$R1000,3,False) -> #N/A | J40: =sumif('SEED INVENTORY'!$T$46:$T1000,A40,'SEED INVENTORY'!$U$46:$U1000) -> 0
A41: =IFERROR(__xludf.DUMMYFUNCTION("""COMPUTED_VALUE"""),"Flexstar (2x2.5 Gal)") -> Flexstar (2x2.5 Gal) | D41: =IFERROR(__xludf.DUMMYFUNCTION("""COMPUTED_VALUE"""),0.0) -> 0 | E41: =IFERROR(__xludf.DUMMYFUNCTION("""COMPUTED_VALUE"""),"Pts") -> Pts | H41: =sumif('SEED INVENTORY'!$P$46:$P1000,A41,'SEED INVENTORY'!$Q$46:$Q1000) -> 0 | I41: =vlookup(A41,'SEED INVENTORY'!$P$46:$R1000,3,False) -> #N/A | J41: =sumif('SEED INVENTORY'!$T$46:$T1000,A41,'SEED INVENTORY'!$U$46:$U1000) -> 0
A42: =IFERROR(__xludf.DUMMYFUNCTION("""COMPUTED_VALUE"""),"Grid Sampling (2.5 ac.)") -> Grid Sampling (2.5 ac.) | D42: =IFERROR(__xludf.DUMMYFUNCTION("""COMPUTED_VALUE"""),0.0) -> 0 | E42: =IFERROR(__xludf.DUMMYFUNCTION("""COMPUTED_VALUE"""),"Acre") -> Acre | H42: =sumif('SEED INVENTORY'!$P$46:$P1000,A42,'SEED INVENTORY'!$Q$46:$Q1000) -> 0 | I42: =vlookup(A42,'SEED INVENTORY'!$P$46:$R1000,3,False) -> #N/A | J42: =sumif('SEED INVENTORY'!$T$46:$T1000,A42,'SEED INVENTORY'!$U$46:$U1000) -> 0
A43: =IFERROR(__xludf.DUMMYFUNCTION("""COMPUTED_VALUE"""),"Grid Sampling (5 ac.)") -> Grid Sampling (5 ac.) | D43: =IFERROR(__xludf.DUMMYFUNCTION("""COMPUTED_VALUE"""),20.400000000000002) -> 20.4 | E43: =IFERROR(__xludf.DUMMYFUNCTION("""COMPUTED_VALUE"""),"Acre") -> Acre | H43: =sumif('SEED INVENTORY'!$P$46:$P1000,A43,'SEED INVENTORY'!$Q$46:$Q1000) -> 0 | I43: =vlookup(A43,'SEED INVENTORY'!$P$46:$R1000,3,False) -> #N/A | J43: =sumif('SEED INVENTORY'!$T$46:$T1000,A43,'SEED INVENTORY'!$U$46:$U1000) -> 0
...

Sheet SEED COMPARISON
A1: =IFERROR(__xludf.DUMMYFUNCTION("IMPORTRANGE(""https://docs.google.com/spreadsheets/d/1ROIDByG8JQ9QnTav5kMbqjv_otDakkYL7H10iPWcU48/edit#gid=1300287554"",""seed!b5:e"")"),44683.0) -> 44683
A2: =IFERROR(__xludf.DUMMYFUNCTION("""COMPUTED_VALUE"""),"Crop (UNDERLINE)") -> Crop (UNDERLINE) | B2: =IFERROR(__xludf.DUMMYFUNCTION("""COMPUTED_VALUE"""),"Brand") -> Brand | C2: =IFERROR(__xludf.DUMMYFUNCTION("""COMPUTED_VALUE"""),"VARIETY") -> VARIETY | D2: =IFERROR(__xludf.DUMMYFUNCTION("""COMPUTED_VALUE"""),"Total Projected Units") -> Total Projected Units | F2: Total Units Ordered | H2: Total Units Delivered | J2: Total Units Returned | L2: Balance
A3: =IFERROR(__xludf.DUMMYFUNCTION("""COMPUTED_VALUE"""),"Barley") -> Barley | B3: =IFERROR(__xludf.DUMMYFUNCTION("""COMPUTED_VALUE"""),"Albert Lea") -> Albert Lea | C3: =IFERROR(__xludf.DUMMYFUNCTION("""COMPUTED_VALUE"""),"SB151") -> SB151 | D3: =IFERROR(__xludf.DUMMYFUNCTION("""COMPUTED_VALUE"""),468.74999999999994) -> 468.75 | F3: =sumif('INVOICE ACCOUNT SUMMARIES'!$A$2:$A1000,C3,'INVOICE ACCOUNT SUMMARIES'!$E$2:$E1000) -> 0 | H3: =sumif('SEED INVENTORY'!$I$46:$I1000,C3,'SEED INVENTORY'!$K$46:$K1000) -> 0 | J3: =sumif('SEED INVENTORY'!$I$46:$I1000,C3,'SEED INVENTORY'!$T$46:$T1000) -> 0 | L3: =H3-J3 -> 0
A4: =IFERROR(__xludf.DUMMYFUNCTION("""COMPUTED_VALUE"""),"Blue_Corn") -> Blue_Corn | B4: =IFERROR(__xludf.DUMMYFUNCTION("""COMPUTED_VALUE"""),"Kentucky Blue Corn") -> Kentucky Blue Corn | C4: =IFERROR(__xludf.DUMMYFUNCTION("""COMPUTED_VALUE"""),"T1081J") -> T1081J | D4: =IFERROR(__xludf.DUMMYFUNCTION("""COMPUTED_VALUE"""),42.9) -> 42.9 | F4: =sumif('INVOICE ACCOUNT SUMMARIES'!$A$2:$A1000,C4,'INVOICE ACCOUNT SUMMARIES'!$E$2:$E1000) -> 0 | H4: =sumif('SEED INVENTORY'!$I$46:$I1000,C4,'SEED INVENTORY'!$K$46:$K1000) -> 50 | J4: =sumif('SEED INVENTORY'!$I$46:$I1000,C4,'SEED INVENTORY'!$T$46:$T1000) -> 0 | L4: =H4-J4 -> 50
A5: =IFERROR(__xludf.DUMMYFUNCTION("""COMPUTED_VALUE"""),"Yellow_Corn") -> Yellow_Corn | B5: =IFERROR(__xludf.DUMMYFUNCTION("""COMPUTED_VALUE"""),"viking") -> viking | C5: =IFERROR(__xludf.DUMMYFUNCTION("""COMPUTED_VALUE"""),"Viking 051-04GS") -> Viking 051-04GS | D5: =IFERROR(__xludf.DUMMYFUNCTION("""COMPUTED_VALUE"""),0.0) -> 0 | F5: =sumif('INVOICE ACCOUNT SUMMARIES'!$A$2:$A1000,C5,'INVOICE ACCOUNT SUMMARIES'!$E$2:$E1000) -> 0 | H5: =sumif('SEED INVENTORY'!$I$46:$I1000,C5,'SEED INVENTORY'!$K$46:$K1000) -> 0 | J5: =sumif('SEED INVENTORY'!$I$46:$I1000,C5,'SEED INVENTORY'!$T$46:$T1000) -> 0 | L5: =H5-J5 -> 0
A6: =IFERROR(__xludf.DUMMYFUNCTION("""COMPUTED_VALUE"""),"Yellow_Corn") -> Yellow_Corn | B6: =IFERROR(__xludf.DUMMYFUNCTION("""COMPUTED_VALUE"""),"Pioneer") -> Pioneer | C6: =IFERROR(__xludf.DUMMYFUNCTION("""COMPUTED_VALUE"""),"P0157") -> P0157 | D6: =IFERROR(__xludf.DUMMYFUNCTION("""COMPUTED_VALUE"""),250.441125) -> 250.44112 | F6: =sumif('INVOICE ACCOUNT SUMMARIES'!$A$2:$A1000,C6,'INVOICE ACCOUNT SUMMARIES'!$E$2:$E1000) -> 0 | H6: =sumif('SEED INVENTORY'!$I$46:$I1000,C6,'SEED INVENTORY'!$K$46:$K1000) -> 0 | J6: =sumif('SEED INVENTORY'!$I$46:$I1000,C6,'SEED INVENTORY'!$T$46:$T1000) -> 0 | L6: =H6-J6 -> 0
A7: =IFERROR(__xludf.DUMMYFUNCTION("""COMPUTED_VALUE"""),"Yellow_Corn") -> Yellow_Corn | B7: =IFERROR(__xludf.DUMMYFUNCTION("""COMPUTED_VALUE"""),"Pioneer") -> Pioneer | C7: =IFERROR(__xludf.DUMMYFUNCTION("""COMPUTED_VALUE"""),"P0075") -> P0075 | D7: =IFERROR(__xludf.DUMMYFUNCTION("""COMPUTED_VALUE"""),0.0) -> 0 | F7: =sumif('INVOICE ACCOUNT SUMMARIES'!$A$2:$A1000,C7,'INVOICE ACCOUNT SUMMARIES'!$E$2:$E1000) -> 0 | H7: =sumif('SEED INVENTORY'!$I$46:$I1000,C7,'SEED INVENTORY'!$K$46:$K1000) -> 0 | J7: =sumif('SEED INVENTORY'!$I$46:$I1000,C7,'SEED INVENTORY'!$T$46:$T1000) -> 0 | L7: =H7-J7 -> 0
A8: =IFERROR(__xludf.DUMMYFUNCTION("""COMPUTED_VALUE"""),"Yellow_Corn") -> Yellow_Corn | B8: =IFERROR(__xludf.DUMMYFUNCTION("""COMPUTED_VALUE"""),"viking") -> viking | C8: =IFERROR(__xludf.DUMMYFUNCTION("""COMPUTED_VALUE"""),"O46-02") -> O46-02 | D8: =IFERROR(__xludf.DUMMYFUNCTION("""COMPUTED_VALUE"""),0.0) -> 0 | F8: =sumif('INVOICE ACCOUNT SUMMARIES'!$A$2:$A1000,C8,'INVOICE ACCOUNT SUMMARIES'!$E$2:$E1000) -> 0 | H8: =sumif('SEED INVENTORY'!$I$46:$I1000,C8,'SEED INVENTORY'!$K$46:$K1000) -> 0 | J8: =sumif('SEED INVENTORY'!$I$46:$I1000,C8,'SEED INVENTORY'!$T$46:$T1000) -> 0 | L8: =H8-J8 -> 0
A9: =IFERROR(__xludf.DUMMYFUNCTION("""COMPUTED_VALUE"""),"Yellow_Corn") -> Yellow_Corn | B9: =IFERROR(__xludf.DUMMYFUNCTION("""COMPUTED_VALUE"""),"viking") -> viking | C9: =IFERROR(__xludf.DUMMYFUNCTION("""COMPUTED_VALUE"""),"O.18-06UP") -> O.18-06UP | D9: =IFERROR(__xludf.DUMMYFUNCTION("""COMPUTED_VALUE"""),198.00000000000003) -> 198 | F9: =sumif('INVOICE ACCOUNT SUMMARIES'!$A$2:$A1000,C9,'INVOICE ACCOUNT SUMMARIES'!$E$2:$E1000) -> 0 | H9: =sumif('SEED INVENTORY'!$I$46:$I1000,C9,'SEED INVENTORY'!$K$46:$K1000) -> 0 | J9: =sumif('SEED INVENTORY'!$I$46:$I1000,C9,'SEED INVENTORY'!$T$46:$T1000) -> 0 | L9: =H9-J9 -> 0
A10: =IFERROR(__xludf.DUMMYFUNCTION("""COMPUTED_VALUE"""),"Yellow_Corn") -> Yellow_Corn | B10: =IFERROR(__xludf.DUMMYFUNCTION("""COMPUTED_VALUE"""),"viking") -> viking | C10: =IFERROR(__xludf.DUMMYFUNCTION("""COMPUTED_VALUE"""),"55-02") -> 55-02 | D10: =IFERROR(__xludf.DUMMYFUNCTION("""COMPUTED_VALUE"""),0.0) -> 0 | F10: =sumif('INVOICE ACCOUNT SUMMARIES'!$A$2:$A1000,C10,'INVOICE ACCOUNT SUMMARIES'!$E$2:$E1000) -> 0 | H10: =sumif('SEED INVENTORY'!$I$46:$I1000,C10,'SEED INVENTORY'!$K$46:$K1000) -> 0 | J10: =sumif('SEED INVENTORY'!$I$46:$I1000,C10,'SEED INVENTORY'!$T$46:$T1000) -> 0 | L10: =H10-J10 -> 0
A11: =IFERROR(__xludf.DUMMYFUNCTION("""COMPUTED_VALUE"""),"Yellow_Corn") -> Yellow_Corn | B11: =IFERROR(__xludf.DUMMYFUNCTION("""COMPUTED_VALUE"""),"viking") -> viking | C11: =IFERROR(__xludf.DUMMYFUNCTION("""COMPUTED_VALUE"""),"51-04") -> 51-04 | D11: =IFERROR(__xludf.DUMMYFUNCTION("""COMPUTED_VALUE"""),0.0) -> 0 | F11: =sumif('INVOICE ACCOUNT SUMMARIES'!$A$2:$A1000,C11,'INVOICE ACCOUNT SUMMARIES'!$E$2:$E1000) -> 0 | H11: =sumif('SEED INVENTORY'!$I$46:$I1000,C11,'SEED INVENTORY'!$K$46:$K1000) -> 0 | J11: =sumif('SEED INVENTORY'!$I$46:$I1000,C11,'SEED INVENTORY'!$T$46:$T1000) -> 0 | L11: =H11-J11 -> 0
A12: =IFERROR(__xludf.DUMMYFUNCTION("""COMPUTED_VALUE"""),"Yellow_Corn") -> Yellow_Corn | B12: =IFERROR(__xludf.DUMMYFUNCTION("""COMPUTED_VALUE"""),"prarie hybrids") -> prarie hybrids | C12: =IFERROR(__xludf.DUMMYFUNCTION("""COMPUTED_VALUE"""),3081.0) -> 3081 | D12: =IFERROR(__xludf.DUMMYFUNCTION("""COMPUTED_VALUE"""),0.0) -> 0 | F12: =sumif('INVOICE ACCOUNT SUMMARIES'!$A$2:$A1000,C12,'INVOICE ACCOUNT SUMMARIES'!$E$2:$E1000) -> 0 | H12: =sumif('SEED INVENTORY'!$I$46:$I1000,C12,'SEED INVENTORY'!$K$46:$K1000) -> 0 | J12: =sumif('SEED INVENTORY'!$I$46:$I1000,C12,'SEED INVENTORY'!$T$46:$T1000) -> 0 | L12: =H12-J12 -> 0
A13: =IFERROR(__xludf.DUMMYFUNCTION("""COMPUTED_VALUE"""),"Yellow_Corn") -> Yellow_Corn | B13: =IFERROR(__xludf.DUMMYFUNCTION("""COMPUTED_VALUE"""),"prarie hybrids") -> prarie hybrids | C13: =IFERROR(__xludf.DUMMYFUNCTION("""COMPUTED_VALUE"""),5351.0) -> 5351 | D13: =IFERROR(__xludf.DUMMYFUNCTION("""COMPUTED_VALUE"""),0.0) -> 0 | F13: =sumif('INVOICE ACCOUNT SUMMARIES'!$A$2:$A1000,C13,'INVOICE ACCOUNT SUMMARIES'!$E$2:$E1000) -> 0 | H13: =sumif('SEED INVENTORY'!$I$46:$I1000,C13,'SEED INVENTORY'!$K$46:$K1000) -> 0 | J13: =sumif('SEED INVENTORY'!$I$46:$I1000,C13,'SEED INVENTORY'!$T$46:$T1000) -> 0 | L13: =H13-J13 -> 0
A14: =IFERROR(__xludf.DUMMYFUNCTION("""COMPUTED_VALUE"""),"Yellow_Corn") -> Yellow_Corn | B14: =IFERROR(__xludf.DUMMYFUNCTION("""COMPUTED_VALUE"""),"Pioneer") -> Pioneer | C14: =IFERROR(__xludf.DUMMYFUNCTION("""COMPUTED_VALUE"""),"P0506") -> P0506 | D14: =IFERROR(__xludf.DUMMYFUNCTION("""COMPUTED_VALUE"""),0.0) -> 0 | F14: =sumif('INVOICE ACCOUNT SUMMARIES'!$A$2:$A1000,C14,'INVOICE ACCOUNT SUMMARIES'!$E$2:$E1000) -> 0 | H14: =sumif('SEED INVENTORY'!$I$46:$I1000,C14,'SEED INVENTORY'!$K$46:$K1000) -> 0 | J14: =sumif('SEED INVENTORY'!$I$46:$I1000,C14,'SEED INVENTORY'!$T$46:$T1000) -> 0 | L14: =H14-J14 -> 0
A15: =IFERROR(__xludf.DUMMYFUNCTION("""COMPUTED_VALUE"""),"Yellow_Corn") -> Yellow_Corn | B15: =IFERROR(__xludf.DUMMYFUNCTION("""COMPUTED_VALUE"""),"Pioneer") -> Pioneer | C15: =IFERROR(__xludf.DUMMYFUNCTION("""COMPUTED_VALUE"""),"P9998") -> P9998 | D15: =IFERROR(__xludf.DUMMYFUNCTION("""COMPUTED_VALUE"""),0.0) -> 0 | F15: =sumif('INVOICE ACCOUNT SUMMARIES'!$A$2:$A1000,C15,'INVOICE ACCOUNT SUMMARIES'!$E$2:$E1000) -> 0 | H15: =sumif('SEED INVENTORY'!$I$46:$I1000,C15,'SEED INVENTORY'!$K$46:$K1000) -> 0 | J15: =sumif('SEED INVENTORY'!$I$46:$I1000,C15,'SEED INVENTORY'!$T$46:$T1000) -> 0 | L15: =H15-J15 -> 0
A16: =IFERROR(__xludf.DUMMYFUNCTION("""COMPUTED_VALUE"""),"Field_pea") -> Field_pea | B16: =IFERROR(__xludf.DUMMYFUNCTION("""COMPUTED_VALUE"""),"puris") -> puris | C16: =IFERROR(__xludf.DUMMYFUNCTION("""COMPUTED_VALUE"""),1804.0) -> 1804 | D16: =IFERROR(__xludf.DUMMYFUNCTION("""COMPUTED_VALUE"""),0.0) -> 0 | F16: =sumif('INVOICE ACCOUNT SUMMARIES'!$A$2:$A1000,C16,'INVOICE ACCOUNT SUMMARIES'!$E$2:$E1000) -> 0 | H16: =sumif('SEED INVENTORY'!$I$46:$I1000,C16,'SEED INVENTORY'!$K$46:$K1000) -> 0 | J16: =sumif('SEED INVENTORY'!$I$46:$I1000,C16,'SEED INVENTORY'!$T$46:$T1000) -> 0 | L16: =H16-J16 -> 0
A17: =IFERROR(__xludf.DUMMYFUNCTION("""COMPUTED_VALUE"""),"Hairy_Vetch") -> Hairy_Vetch | B17: =IFERROR(__xludf.DUMMYFUNCTION("""COMPUTED_VALUE"""),"Albert Lea") -> Albert Lea | C17: =IFERROR(__xludf.DUMMYFUNCTION("""COMPUTED_VALUE"""),"VNS vetch") -> VNS vetch | D17: =IFERROR(__xludf.DUMMYFUNCTION("""COMPUTED_VALUE"""),0.0) -> 0 | F17: =sumif('INVOICE ACCOUNT SUMMARIES'!$A$2:$A1000,C17,'INVOICE ACCOUNT SUMMARIES'!$E$2:$E1000) -> 0 | H17: =sumif('SEED INVENTORY'!$I$46:$I1000,C17,'SEED INVENTORY'!$K$46:$K1000) -> 0 | J17: =sumif('SEED INVENTORY'!$I$46:$I1000,C17,'SEED INVENTORY'!$T$46:$T1000) -> 0 | L17: =H17-J17 -> 0
A18: =IFERROR(__xludf.DUMMYFUNCTION("""COMPUTED_VALUE"""),"Hybrid_Rye") -> Hybrid_Rye | B18: =IFERROR(__xludf.DUMMYFUNCTION("""COMPUTED_VALUE"""),"KWS") -> KWS | C18: =IFERROR(__xludf.DUMMYFUNCTION("""COMPUTED_VALUE"""),"Serafino - Parent") -> Serafino - Parent | D18: =IFERROR(__xludf.DUMMYFUNCTION("""COMPUTED_VALUE"""),0.0) -> 0 | F18: =sumif('INVOICE ACCOUNT SUMMARIES'!$A$2:$A1000,C18,'INVOICE ACCOUNT SUMMARIES'!$E$2:$E1000) -> 0 | H18: =sumif('SEED INVENTORY'!$I$46:$I1000,C18,'SEED INVENTORY'!$K$46:$K1000) -> 0 | J18: =sumif('SEED INVENTORY'!$I$46:$I1000,C18,'SEED INVENTORY'!$T$46:$T1000) -> 0 | L18: =H18-J18 -> 0
A19: =IFERROR(__xludf.DUMMYFUNCTION("""COMPUTED_VALUE"""),"Hybrid_Rye") -> Hybrid_Rye | B19: =IFERROR(__xludf.DUMMYFUNCTION("""COMPUTED_VALUE"""),"KWS") -> KWS | C19: =IFERROR(__xludf.DUMMYFUNCTION("""COMPUTED_VALUE"""),"Serafino - restorer") -> Serafino - restorer | D19: =IFERROR(__xludf.DUMMYFUNCTION("""COMPUTED_VALUE"""),0.0) -> 0 | F19: =sumif('INVOICE ACCOUNT SUMMARIES'!$A$2:$A1000,C19,'INVOICE ACCOUNT SUMMARIES'!$E$2:$E1000) -> 0 | H19: =sumif('SEED INVENTORY'!$I$46:$I1000,C19,'SEED INVENTORY'!$K$46:$K1000) -> 0 | J19: =sumif('SEED INVENTORY'!$I$46:$I1000,C19,'SEED INVENTORY'!$T$46:$T1000) -> 0 | L19: =H19-J19 -> 0
A20: =IFERROR(__xludf.DUMMYFUNCTION("""COMPUTED_VALUE"""),"Kernza") -> Kernza | B20: =IFERROR(__xludf.DUMMYFUNCTION("""COMPUTED_VALUE"""),"TLI") -> TLI | C20: =IFERROR(__xludf.DUMMYFUNCTION("""COMPUTED_VALUE"""),"MN Clearwater") -> MN Clearwater | D20: =IFERROR(__xludf.DUMMYFUNCTION("""COMPUTED_VALUE"""),0.0) -> 0 | F20: =sumif('INVOICE ACCOUNT SUMMARIES'!$A$2:$A1000,C20,'INVOICE ACCOUNT SUMMARIES'!$E$2:$E1000) -> 0 | H20: =sumif('SEED INVENTORY'!$I$46:$I1000,C20,'SEED INVENTORY'!$K$46:$K1000) -> 0 | J20: =sumif('SEED INVENTORY'!$I$46:$I1000,C20,'SEED INVENTORY'!$T$46:$T1000) -> 0 | L20: =H20-J20 -> 0
A21: =IFERROR(__xludf.DUMMYFUNCTION("""COMPUTED_VALUE"""),"None") -> None | B21: =IFERROR(__xludf.DUMMYFUNCTION("""COMPUTED_VALUE"""),"none") -> none | C21: =IFERROR(__xludf.DUMMYFUNCTION("""COMPUTED_VALUE"""),"none") -> none | D21: =IFERROR(__xludf.DUMMYFUNCTION("""COMPUTED_VALUE"""),0.0) -> 0 | F21: =sumif('INVOICE ACCOUNT SUMMARIES'!$A$2:$A1000,C21,'INVOICE ACCOUNT SUMMARIES'!$E$2:$E1000) -> 0 | H21: =sumif('SEED INVENTORY'!$I$46:$I1000,C21,'SEED INVENTORY'!$K$46:$K1000) -> 0 | J21: =sumif('SEED INVENTORY'!$I$46:$I1000,C21,'SEED INVENTORY'!$T$46:$T1000) -> 0 | L21: =H21-J21 -> 0
A22: =IFERROR(__xludf.DUMMYFUNCTION("""COMPUTED_VALUE"""),"Rye") -> Rye | B22: =IFERROR(__xludf.DUMMYFUNCTION("""COMPUTED_VALUE"""),"Albert Lea") -> Albert Lea | C22: =IFERROR(__xludf.DUMMYFUNCTION("""COMPUTED_VALUE"""),"Hazlett") -> Hazlett | D22: =IFERROR(__xludf.DUMMYFUNCTION("""COMPUTED_VALUE"""),0.0) -> 0 | F22: =sumif('INVOICE ACCOUNT SUMMARIES'!$A$2:$A1000,C22,'INVOICE ACCOUNT SUMMARIES'!$E$2:$E1000) -> 0 | H22: =sumif('SEED INVENTORY'!$I$46:$I1000,C22,'SEED INVENTORY'!$K$46:$K1000) -> 0 | J22: =sumif('SEED INVENTORY'!$I$46:$I1000,C22,'SEED INVENTORY'!$T$46:$T1000) -> 0 | L22: =H22-J22 -> 0
A23: =IFERROR(__xludf.DUMMYFUNCTION("""COMPUTED_VALUE"""),"SEED_CORN") -> SEED_CORN | C23: =IFERROR(__xludf.DUMMYFUNCTION("""COMPUTED_VALUE"""),"SEED CORN") -> SEED CORN | D23: =IFERROR(__xludf.DUMMYFUNCTION("""COMPUTED_VALUE"""),0.0) -> 0 | F23: =sumif('INVOICE ACCOUNT SUMMARIES'!$A$2:$A1000,C23,'INVOICE ACCOUNT SUMMARIES'!$E$2:$E1000) -> 0 | H23: =sumif('SEED INVENTORY'!$I$46:$I1000,C23,'SEED INVENTORY'!$K$46:$K1000) -> 0 | J23: =sumif('SEED INVENTORY'!$I$46:$I1000,C23,'SEED INVENTORY'!$T$46:$T1000) -> 0 | L23: =H23-J23 -> 0
A24: =IFERROR(__xludf.DUMMYFUNCTION("""COMPUTED_VALUE"""),"Sorghum") -> Sorghum | B24: =IFERROR(__xludf.DUMMYFUNCTION("""COMPUTED_VALUE"""),"Pioneer") -> Pioneer | C24: =IFERROR(__xludf.DUMMYFUNCTION("""COMPUTED_VALUE"""),"89Y78") -> 89Y78 | D24: =IFERROR(__xludf.DUMMYFUNCTION("""COMPUTED_VALUE"""),20.991951219512192) -> 20.991951 | F24: =sumif('INVOICE ACCOUNT SUMMARIES'!$A$2:$A1000,C24,'INVOICE ACCOUNT SUMMARIES'!$E$2:$E1000) -> 0 | H24: =sumif('SEED INVENTORY'!$I$46:$I1000,C24,'SEED INVENTORY'!$K$46:$K1000) -> 0 | J24: =sumif('SEED INVENTORY'!$I$46:$I1000,C24,'SEED INVENTORY'!$T$46:$T1000) -> 0 | L24: =H24-J24 -> 0
A25: =IFERROR(__xludf.DUMMYFUNCTION("""COMPUTED_VALUE"""),"sorghum") -> sorghum | B25: =IFERROR(__xludf.DUMMYFUNCTION("""COMPUTED_VALUE"""),"Pioneer") -> Pioneer | C25: =IFERROR(__xludf.DUMMYFUNCTION("""COMPUTED_VALUE"""),"87P06") -> 87P06 | D25: =IFERROR(__xludf.DUMMYFUNCTION("""COMPUTED_VALUE"""),0.0) -> 0 | F25: =sumif('INVOICE ACCOUNT SUMMARIES'!$A$2:$A1000,C25,'INVOICE ACCOUNT SUMMARIES'!$E$2:$E1000) -> 0 | H25: =sumif('SEED INVENTORY'!$I$46:$I1000,C25,'SEED INVENTORY'!$K$46:$K1000) -> 0 | J25: =sumif('SEED INVENTORY'!$I$46:$I1000,C25,'SEED INVENTORY'!$T$46:$T1000) -> 0 | L25: =H25-J25 -> 0
A26: =IFERROR(__xludf.DUMMYFUNCTION("""COMPUTED_VALUE"""),"Soybeans") -> Soybeans | B26: =IFERROR(__xludf.DUMMYFUNCTION("""COMPUTED_VALUE"""),"Pioneer") -> Pioneer | C26: =IFERROR(__xludf.DUMMYFUNCTION("""COMPUTED_VALUE"""),"21A20") -> 21A20 | D26: =IFERROR(__xludf.DUMMYFUNCTION("""COMPUTED_VALUE"""),742.4999999999999) -> 742.5 | F26: =sumif('INVOICE ACCOUNT SUMMARIES'!$A$2:$A1000,C26,'INVOICE ACCOUNT SUMMARIES'!$E$2:$E1000) -> 0 | G26: units | H26: =sumif('SEED INVENTORY'!$I$46:$I1000,C26,'SEED INVENTORY'!$K$46:$K1000) -> 0 | J26: =sumif('SEED INVENTORY'!$I$46:$I1000,C26,'SEED INVENTORY'!$T$46:$T1000) -> 0 | L26: =H26-J26 -> 0
A27: =IFERROR(__xludf.DUMMYFUNCTION("""COMPUTED_VALUE"""),"Soybeans") -> Soybeans | B27: =IFERROR(__xludf.DUMMYFUNCTION("""COMPUTED_VALUE"""),"Legend seed") -> Legend seed | C27: =IFERROR(__xludf.DUMMYFUNCTION("""COMPUTED_VALUE"""),2580.0) -> 2580 | D27: =IFERROR(__xludf.DUMMYFUNCTION("""COMPUTED_VALUE"""),319.09090909090907) -> 319.09091 | F27: =sumif('INVOICE ACCOUNT SUMMARIES'!$A$2:$A1000,C27,'INVOICE ACCOUNT SUMMARIES'!$E$2:$E1000) -> 0 | H27: =sumif('SEED INVENTORY'!$I$46:$I1000,C27,'SEED INVENTORY'!$K$46:$K1000) -> 0 | J27: =sumif('SEED INVENTORY'!$I$46:$I1000,C27,'SEED INVENTORY'!$T$46:$T1000) -> 0 | L27: =H27-J27 -> 0
A28: =IFERROR(__xludf.DUMMYFUNCTION("""COMPUTED_VALUE"""),"Soybeans") -> Soybeans | B28: =IFERROR(__xludf.DUMMYFUNCTION("""COMPUTED_VALUE"""),"Pioneer") -> Pioneer | C28: =IFERROR(__xludf.DUMMYFUNCTION("""COMPUTED_VALUE"""),"RR Beans") -> RR Beans | D28: =IFERROR(__xludf.DUMMYFUNCTION("""COMPUTED_VALUE"""),0.0) -> 0 | F28: =sumif('INVOICE ACCOUNT SUMMARIES'!$A$2:$A1000,C28,'INVOICE ACCOUNT SUMMARIES'!$E$2:$E1000) -> 0 | G28: units | H28: =sumif('SEED INVENTORY'!$I$46:$I1000,C28,'SEED INVENTORY'!$K$46:$K1000) -> 0 | J28: =sumif('SEED INVENTORY'!$I$46:$I1000,C28,'SEED INVENTORY'!$T$46:$T1000) -> 0 | L28: =H28-J28 -> 0
A29: =IFERROR(__xludf.DUMMYFUNCTION("""COMPUTED_VALUE"""),"Soybeans") -> Soybeans | B29: =IFERROR(__xludf.DUMMYFUNCTION("""COMPUTED_VALUE"""),"viking") -> viking | C29: =IFERROR(__xludf.DUMMYFUNCTION("""COMPUTED_VALUE"""),"VIKING 2188") -> VIKING 2188 | D29: =IFERROR(__xludf.DUMMYFUNCTION("""COMPUTED_VALUE"""),289.39285714285717) -> 289.39286 | F29: =sumif('INVOICE ACCOUNT SUMMARIES'!$A$2:$A1000,C29,'INVOICE ACCOUNT SUMMARIES'!$E$2:$E1000) -> 0 | H29: =sumif('SEED INVENTORY'!$I$46:$I1000,C29,'SEED INVENTORY'!$K$46:$K1000) -> -9 | J29: =sumif('SEED INVENTORY'!$I$46:$I1000,C29,'SEED INVENTORY'!$T$46:$T1000) -> 0 | L29: =H29-J29 -> -9
A30: =IFERROR(__xludf.DUMMYFUNCTION("""COMPUTED_VALUE"""),"Soybeans") -> Soybeans | B30: =IFERROR(__xludf.DUMMYFUNCTION("""COMPUTED_VALUE"""),"puris") -> puris | C30: =IFERROR(__xludf.DUMMYFUNCTION("""COMPUTED_VALUE"""),"Puris food bean") -> Puris food bean | D30: =IFERROR(__xludf.DUMMYFUNCTION("""COMPUTED_VALUE"""),0.0) -> 0 | F30: =sumif('INVOICE ACCOUNT SUMMARIES'!$A$2:$A1000,C30,'INVOICE ACCOUNT SUMMARIES'!$E$2:$E1000) -> 0 | G30: units | H30: =sumif('SEED INVENTORY'!$I$46:$I1000,C30,'SEED INVENTORY'!$K$46:$K1000) -> 0 | J30: =sumif('SEED INVENTORY'!$I$46:$I1000,C30,'SEED INVENTORY'!$T$46:$T1000) -> 0 | L30: =H30-J30 -> 0
A31: =IFERROR(__xludf.DUMMYFUNCTION("""COMPUTED_VALUE"""),"Sunflowers") -> Sunflowers | B31: =IFERROR(__xludf.DUMMYFUNCTION("""COMPUTED_VALUE"""),"Pioneer") -> Pioneer | C31: =IFERROR(__xludf.DUMMYFUNCTION("""COMPUTED_VALUE"""),"P63HE90") -> P63HE90 | D31: =IFERROR(__xludf.DUMMYFUNCTION("""COMPUTED_VALUE"""),0.0) -> 0 | F31: =sumif('INVOICE ACCOUNT SUMMARIES'!$A$2:$A1000,C31,'INVOICE ACCOUNT SUMMARIES'!$E$2:$E1000) -> 0 | H31: =sumif('SEED INVENTORY'!$I$46:$I1000,C31,'SEED INVENTORY'!$K$46:$K1000) -> 0 | J31: =sumif('SEED INVENTORY'!$I$46:$I1000,C31,'SEED INVENTORY'!$T$46:$T1000) -> 0 | L31: =H31-J31 -> 0
A32: =IFERROR(__xludf.DUMMYFUNCTION("""COMPUTED_VALUE"""),"Wheat") -> Wheat | C32: =IFERROR(__xludf.DUMMYFUNCTION("""COMPUTED_VALUE"""),"sunburst") -> sunburst | D32: =IFERROR(__xludf.DUMMYFUNCTION("""COMPUTED_VALUE"""),0.0) -> 0 | F32: =sumif('INVOICE ACCOUNT SUMMARIES'!$A$2:$A1000,C32,'INVOICE ACCOUNT SUMMARIES'!$E$2:$E1000) -> 0 | G32: units | H32: =sumif('SEED INVENTORY'!$I$46:$I1000,C32,'SEED INVENTORY'!$K$46:$K1000) -> 0 | J32: =sumif('SEED INVENTORY'!$I$46:$I1000,C32,'SEED INVENTORY'!$T$46:$T1000) -> 0 | L32: =H32-J32 -> 0
A33: =IFERROR(__xludf.DUMMYFUNCTION("""COMPUTED_VALUE"""),"Wheat") -> Wheat | B33: =IFERROR(__xludf.DUMMYFUNCTION("""COMPUTED_VALUE"""),"Limagrain") -> Limagrain | C33: =IFERROR(__xludf.DUMMYFUNCTION("""COMPUTED_VALUE"""),"LCS 3334") -> LCS 3334 | D33: =IFERROR(__xludf.DUMMYFUNCTION("""COMPUTED_VALUE"""),577.9663374600084) -> 577.96634 | F33: =sumif('INVOICE ACCOUNT SUMMARIES'!$A$2:$A1000,C33,'INVOICE ACCOUNT SUMMARIES'!$E$2:$E1000) -> 0 | G33: units | H33: =sumif('SEED INVENTORY'!$I$46:$I1000,C33,'SEED INVENTORY'!$K$46:$K1000) -> 0 | J33: =sumif('SEED INVENTORY'!$I$46:$I1000,C33,'SEED INVENTORY'!$T$46:$T1000) -> 0 | L33: =H33-J33 -> 0
A34: =IFERROR(__xludf.DUMMYFUNCTION("""COMPUTED_VALUE"""),"Wheat") -> Wheat | B34: =IFERROR(__xludf.DUMMYFUNCTION("""COMPUTED_VALUE"""),"Pioneer") -> Pioneer | C34: =IFERROR(__xludf.DUMMYFUNCTION("""COMPUTED_VALUE"""),"25R34 N3431") -> 25R34 N3431 | D34: =IFERROR(__xludf.DUMMYFUNCTION("""COMPUTED_VALUE"""),0.0) -> 0 | F34: =sumif('INVOICE ACCOUNT SUMMARIES'!$A$2:$A1000,C34,'INVOICE ACCOUNT SUMMARIES'!$E$2:$E1000) -> 0 | H34: =sumif('SEED INVENTORY'!$I$46:$I1000,C34,'SEED INVENTORY'!$K$46:$K1000) -> 0 | J34: =sumif('SEED INVENTORY'!$I$46:$I1000,C34,'SEED INVENTORY'!$T$46:$T1000) -> 0 | L34: =H34-J34 -> 0
A35: =IFERROR(__xludf.DUMMYFUNCTION("""COMPUTED_VALUE"""),"Wheat") -> Wheat | B35: =IFERROR(__xludf.DUMMYFUNCTION("""COMPUTED_VALUE"""),"Kennel Seed") -> Kennel Seed | C35: =IFERROR(__xludf.DUMMYFUNCTION("""COMPUTED_VALUE"""),"KS- 1618") -> KS- 1618 | D35: =IFERROR(__xludf.DUMMYFUNCTION("""COMPUTED_VALUE"""),0.0) -> 0 | F35: =sumif('INVOICE ACCOUNT SUMMARIES'!$A$2:$A1000,C35,'INVOICE ACCOUNT SUMMARIES'!$E$2:$E1000) -> 0 | H35: =sumif('SEED INVENTORY'!$I$46:$I1000,C35,'SEED INVENTORY'!$K$46:$K1000) -> 0 | J35: =sumif('SEED INVENTORY'!$I$46:$I1000,C35,'SEED INVENTORY'!$T$46:$T1000) -> 0 | L35: =H35-J35 -> 0
A36: =IFERROR(__xludf.DUMMYFUNCTION("""COMPUTED_VALUE"""),"White_Corn") -> White_Corn | B36: =IFERROR(__xludf.DUMMYFUNCTION("""COMPUTED_VALUE"""),"Pioneer") -> Pioneer | C36: =IFERROR(__xludf.DUMMYFUNCTION("""COMPUTED_VALUE"""),"1306W") -> 1306W | D36: =IFERROR(__xludf.DUMMYFUNCTION("""COMPUTED_VALUE"""),303.4375) -> 303.4375 | F36: =sumif('INVOICE ACCOUNT SUMMARIES'!$A$2:$A1000,C36,'INVOICE ACCOUNT SUMMARIES'!$E$2:$E1000) -> 0 | H36: =sumif('SEED INVENTORY'!$I$46:$I1000,C36,'SEED INVENTORY'!$K$46:$K1000) -> 0 | J36: =sumif('SEED INVENTORY'!$I$46:$I1000,C36,'SEED INVENTORY'!$T$46:$T1000) -> 0 | L36: =H36-J36 -> 0
A37: =IFERROR(__xludf.DUMMYFUNCTION("""COMPUTED_VALUE"""),"White_Corn") -> White_Corn | B37: =IFERROR(__xludf.DUMMYFUNCTION("""COMPUTED_VALUE"""),"Pioneer") -> Pioneer | C37: =IFERROR(__xludf.DUMMYFUNCTION("""COMPUTED_VALUE"""),"1306W untreated") -> 1306W untreated | D37: =IFERROR(__xludf.DUMMYFUNCTION("""COMPUTED_VALUE"""),0.0) -> 0 | F37: =sumif('INVOICE ACCOUNT SUMMARIES'!$A$2:$A1000,C37,'INVOICE ACCOUNT SUMMARIES'!$E$2:$E1000) -> 0 | H37: =sumif('SEED INVENTORY'!$I$46:$I1000,C37,'SEED INVENTORY'!$K$46:$K1000) -> 0 | J37: =sumif('SEED INVENTORY'!$I$46:$I1000,C37,'SEED INVENTORY'!$T$46:$T1000) -> 0 | L37: =H37-J37 -> 0
C38: =IFERROR(__xludf.DUMMYFUNCTION("""COMPUTED_VALUE"""),"CANNING") -> CANNING | D38: =IFERROR(__xludf.DUMMYFUNCTION("""COMPUTED_VALUE"""),1772.216041666667) -> 1772.216 | F38: =sumif('INVOICE ACCOUNT SUMMARIES'!$A$2:$A1000,C38,'INVOICE ACCOUNT SUMMARIES'!$E$2:$E1000) -> 0 | H38: =sumif('SEED INVENTORY'!$I$46:$I1000,C38,'SEED INVENTORY'!$K$46:$K1000) -> 0 | J38: =sumif('SEED INVENTORY'!$I$46:$I1000,C38,'SEED INVENTORY'!$T$46:$T1000) -> 0 | L38: =H38-J38 -> 0
A39: =IFERROR(__xludf.DUMMYFUNCTION("""COMPUTED_VALUE"""),"AlFALFA") -> AlFALFA | B39: =IFERROR(__xludf.DUMMYFUNCTION("""COMPUTED_VALUE"""),"Pioneer") -> Pioneer | C39: =IFERROR(__xludf.DUMMYFUNCTION("""COMPUTED_VALUE"""),"54VQ52") -> 54VQ52 | D39: =IFERROR(__xludf.DUMMYFUNCTION("""COMPUTED_VALUE"""),0.0) -> 0 | F39: =sumif('INVOICE ACCOUNT SUMMARIES'!$A$2:$A1000,C39,'INVOICE ACCOUNT SUMMARIES'!$E$2:$E1000) -> 0 | H39: =sumif('SEED INVENTORY'!$I$46:$I1000,C39,'SEED INVENTORY'!$K$46:$K1000) -> 0 | J39: =sumif('SEED INVENTORY'!$I$46:$I1000,C39,'SEED INVENTORY'!$T$46:$T1000) -> 0 | L39: =H39-J39 -> 0
A40: =IFERROR(__xludf.DUMMYFUNCTION("""COMPUTED_VALUE"""),"ALFALFA") -> ALFALFA | B40: =IFERROR(__xludf.DUMMYFUNCTION("""COMPUTED_VALUE"""),"Haravatron") -> Haravatron | C40: =IFERROR(__xludf.DUMMYFUNCTION("""COMPUTED_VALUE"""),"Harvatron") -> Harvatron | D40: =IFERROR(__xludf.DUMMYFUNCTION("""COMPUTED_VALUE"""),0.0) -> 0 | F40: =sumif('INVOICE ACCOUNT SUMMARIES'!$A$2:$A1000,C40,'INVOICE ACCOUNT SUMMARIES'!$E$2:$E1000) -> 0 | H40: =sumif('SEED INVENTORY'!$I$46:$I1000,C40,'SEED INVENTORY'!$K$46:$K1000) -> 0 | J40: =sumif('SEED INVENTORY'!$I$46:$I1000,C40,'SEED INVENTORY'!$T$46:$T1000) -> 0 | L40: =H40-J40 -> 0
...

Sheet MATRIX
A1: SUB-SUB_GROUP | B1: VARIETIES | U1: product type | V1: in/out | W1: name
A2: SUNFLOWERS | B2: SORGHUM | C2: SOYBEANS | D2: YELLOW_CORN | E2: WHITE_CORN | F2: WHEAT | G2: ALFALFA | H2: HYBRID_RYE | I2: BLUE_CORN | J2: LIMA_BEANS | K2: SEED_CORN | L2: SNAP_BEANS | M2: PEAS | N2: OATS | O2: BARLEY | P2: TREATMENT | R2: PACK TYPE | S2: BRAND | T2: UNIT TYPE | U2: Seed | V2: Incoming | W2: Randy
A3: P63HE90 | B3: 87P06 | C3: P21A20 | D3: Viking 051-04GS | E3: P1306W | F3: sunburst | G3: 54B66 | H3: Seraphino_Parent | I3: RBV-7000 | J3: Meadow | K3: 5G1922BF.0 | L3: HUNTINGTON | M3: 518 | N3: Ogle | O3: SB151 | R3: PROBOX | T3: LBS | U3: Input | V3: return | W3: Robert
A4: Cobalt II | B4: 89Y79 | C4: 92M10 | D4: P0157 | E4: 8508W | F4: LCS 3334 | H4: Seraphino_Parent | K4: GAA2020WG.1 | L4: HERCULES | M4: 520 | R4: SOFT TOTE | T4: BU | W4: Tim
A5: N4H302 | C5: Dairyland_2400 | D5: O46-02 | E5: X3083 | F5: 25R34 N3431 | K5: HID4323WE | R5: Bag | T5: GAL | W5: Gary
C6: VIKING 2188 | D6: O.18-06UP | F6: KS- 1618 | R6: pallet | T6: OZ | W6: Tristan
D7: 55-02 | R7: 2.5 gal JUG | T7: Pints | W7: Julianne
D8: 51-04 | R8: 5 Lbs Box | T8: Bag | W8: Sandy
R9: 15 Gal Box | T9: Box | W9: jason
D10: 3081 | R10: Lbs | T10: Tons | W10: Willie
D11: 5351 | R11: Bu | T11: Units | W11: Nico
D12: P0506 | R12: Units | T12: Yards | W12: Other
D13: P9998 | R13: Gallons | W13: Mike J
R14: Ounces | W14: Bob
R15: EMPTY PROBOX
R16: cases
R17: EMPTY JUG
R18: Units in PROBOX
R19: 80k Paper bag
R20: 80k Unit PROBOX
R21: 140 k Rep Bin fill
R22: 50lb Paper Bag
R23: 200MK Paper Bag
R24: Bulk

Sheet INVOICE ACCOUNT SUMMARIES
A1: Product | C1: Notes | D1: Invoice Type | E1: Units Invoiced | F1: Unit Type | G1: Price Per Unit | H1: Share Gross Invoice Value | I1: Average Price per Unit | J1: Date invoiced | K1: Paid? | L1: Vendor
H27: =E27*G27 -> 0 | K27: FALSE
H28: =E28*G28 -> 0 | K28: FALSE
H29: =E29*G29 -> 0 | K29: FALSE
H30: =E30*G30 -> 0 | K30: FALSE
H31: =E31*G31 -> 0 | K31: FALSE
H32: =E32*G32 -> 0 | K32: FALSE
H33: =E33*G33 -> 0 | K33: FALSE
H34: =E34*G34 -> 0 | K34: FALSE
H35: =E35*G35 -> 0 | K35: FALSE
H36: =E36*G36 -> 0 | K36: FALSE
H37: =E37*G37 -> 0 | K37: FALSE
H38: =E38*G38 -> 0 | K38: FALSE
... H75: =E75*G75 -> 0 | K75: FALSE

Sheet MACRO SEED SHEET
A1: =IFERROR(__xludf.DUMMYFUNCTION("IMPORTRANGE(""https://docs.google.com/spreadsheets/d/1ROIDByG8JQ9QnTav5kMbqjv_otDakkYL7H10iPWcU48/edit#gid=1300287554"",""seed!a1:e"")"),"")
E4: =IFERROR(__xludf.DUMMYFUNCTION("""COMPUTED_VALUE"""),"total seed:") -> total seed:
A5: =IFERROR(__xludf.DUMMYFUNCTION("""COMPUTED_VALUE"""),"LAST EDIT") -> LAST EDIT | B5: =IFERROR(__xludf.DUMMYFUNCTION("""COMPUTED_VALUE"""),44683.0) -> 44683 | L5: =IFERROR(__xludf.DUMMYFUNCTION("IMPORTRANGE(""https://docs.google.com/spreadsheets/d/1ROIDByG8JQ9QnTav5kMbqjv_otDakkYL7H10iPWcU48/edit#gid=259472266"",""Inputs!z1:AA"")"),1224979.9352554143) -> 1224979.9
A6: =IFERROR(__xludf.DUMMYFUNCTION("""COMPUTED_VALUE"""),"Units Ordered") -> Units Ordered | B6: =IFERROR(__xludf.DUMMYFUNCTION("""COMPUTED_VALUE"""),"Crop (UNDERLINE)") -> Crop (UNDERLINE) | C6: =IFERROR(__xludf.DUMMYFUNCTION("""COMPUTED_VALUE"""),"Brand") -> Brand | D6: =IFERROR(__xludf.DUMMYFUNCTION("""COMPUTED_VALUE"""),"VARIETY") -> VARIETY | E6: =IFERROR(__xludf.DUMMYFUNCTION("""COMPUTED_VALUE"""),"Total Projected Units") -> Total Projected Units | I6: =IFERROR(__xludf.DUMMYFUNCTION("IMPORTRANGE(""https://docs.google.com/spreadsheets/d/1ROIDByG8JQ9QnTav5kMbqjv_otDakkYL7H10iPWcU48/edit#gid=259472266"",""Inputs!A1:A"")"),"FERTILLIZER AND CHEMICAL") -> FERTILLIZER AND CHEMICAL | L6: =IFERROR(__xludf.DUMMYFUNCTION("""COMPUTED_VALUE"""),"TOTAL DOLLARS") -> TOTAL DOLLARS | M6: =IFERROR(__xludf.DUMMYFUNCTION("""COMPUTED_VALUE"""),"TOTAL PROJECTED UNITS") -> TOTAL PROJECTED UNITS
B7: =IFERROR(__xludf.DUMMYFUNCTION("""COMPUTED_VALUE"""),"Barley") -> Barley | C7: =IFERROR(__xludf.DUMMYFUNCTION("""COMPUTED_VALUE"""),"Albert Lea") -> Albert Lea | D7: =IFERROR(__xludf.DUMMYFUNCTION("""COMPUTED_VALUE"""),"SB151") -> SB151 | E7: =IFERROR(__xludf.DUMMYFUNCTION("""COMPUTED_VALUE"""),468.74999999999994) -> 468.75 | I7: =IFERROR(__xludf.DUMMYFUNCTION("""COMPUTED_VALUE"""),"Product") -> Product | L7: =IFERROR(__xludf.DUMMYFUNCTION("""COMPUTED_VALUE"""),68192.0674911) -> 68192.067 | M7: =IFERROR(__xludf.DUMMYFUNCTION("""COMPUTED_VALUE"""),253974.18059999996) -> 253974.18
B8: =IFERROR(__xludf.DUMMYFUNCTION("""COMPUTED_VALUE"""),"Blue_Corn") -> Blue_Corn | C8: =IFERROR(__xludf.DUMMYFUNCTION("""COMPUTED_VALUE"""),"Kentucky Blue Corn") -> Kentucky Blue Corn | D8: =IFERROR(__xludf.DUMMYFUNCTION("""COMPUTED_VALUE"""),"T1081J") -> T1081J | E8: =IFERROR(__xludf.DUMMYFUNCTION("""COMPUTED_VALUE"""),42.9) -> 42.9 | I8: =IFERROR(__xludf.DUMMYFUNCTION("""COMPUTED_VALUE"""),"0-0-60 Potash") -> 0-0-60 Potash | L8: =IFERROR(__xludf.DUMMYFUNCTION("""COMPUTED_VALUE"""),35471.73150510205) -> 35471.732 | M8: =IFERROR(__xludf.DUMMYFUNCTION("""COMPUTED_VALUE"""),7506.950000000001) -> 7506.95
B9: =IFERROR(__xludf.DUMMYFUNCTION("""COMPUTED_VALUE"""),"Yellow_Corn") -> Yellow_Corn | C9: =IFERROR(__xludf.DUMMYFUNCTION("""COMPUTED_VALUE"""),"viking") -> viking | D9: =IFERROR(__xludf.DUMMYFUNCTION("""COMPUTED_VALUE"""),"Viking 051-04GS") -> Viking 051-04GS | E9: =IFERROR(__xludf.DUMMYFUNCTION("""COMPUTED_VALUE"""),0.0) -> 0 | I9: =IFERROR(__xludf.DUMMYFUNCTION("""COMPUTED_VALUE"""),"10-34-0") -> 10-34-0 | L9: =IFERROR(__xludf.DUMMYFUNCTION("""COMPUTED_VALUE"""),29966.5226805) -> 29966.523 | M9: =IFERROR(__xludf.DUMMYFUNCTION("""COMPUTED_VALUE"""),94382.74859999999) -> 94382.749
B10: =IFERROR(__xludf.DUMMYFUNCTION("""COMPUTED_VALUE"""),"Yellow_Corn") -> Yellow_Corn | C10: =IFERROR(__xludf.DUMMYFUNCTION("""COMPUTED_VALUE"""),"Pioneer") -> Pioneer | D10: =IFERROR(__xludf.DUMMYFUNCTION("""COMPUTED_VALUE"""),"P0157") -> P0157 | E10: =IFERROR(__xludf.DUMMYFUNCTION("""COMPUTED_VALUE"""),250.441125) -> 250.44112 | I10: =IFERROR(__xludf.DUMMYFUNCTION("""COMPUTED_VALUE"""),"12-0-0-26 Amm Thio") -> 12-0-0-26 Amm Thio | L10: =IFERROR(__xludf.DUMMYFUNCTION("""COMPUTED_VALUE"""),0.0) -> 0 | M10: =IFERROR(__xludf.DUMMYFUNCTION("""COMPUTED_VALUE"""),0.0) -> 0
B11: =IFERROR(__xludf.DUMMYFUNCTION("""COMPUTED_VALUE"""),"Yellow_Corn") -> Yellow_Corn | C11: =IFERROR(__xludf.DUMMYFUNCTION("""COMPUTED_VALUE"""),"Pioneer") -> Pioneer | D11: =IFERROR(__xludf.DUMMYFUNCTION("""COMPUTED_VALUE"""),"P0075") -> P0075 | E11: =IFERROR(__xludf.DUMMYFUNCTION("""COMPUTED_VALUE"""),0.0) -> 0 | I11: =IFERROR(__xludf.DUMMYFUNCTION("""COMPUTED_VALUE"""),"13-0-0-15 Zn (Gal)") -> 13-0-0-15 Zn (Gal) | L11: =IFERROR(__xludf.DUMMYFUNCTION("""COMPUTED_VALUE"""),8846.748781900002) -> 8846.7488 | M11: =IFERROR(__xludf.DUMMYFUNCTION("""COMPUTED_VALUE"""),24578.74) -> 24578.74
B12: =IFERROR(__xludf.DUMMYFUNCTION("""COMPUTED_VALUE"""),"Yellow_Corn") -> Yellow_Corn | C12: =IFERROR(__xludf.DUMMYFUNCTION("""COMPUTED_VALUE"""),"viking") -> viking | D12: =IFERROR(__xludf.DUMMYFUNCTION("""COMPUTED_VALUE"""),"O46-02") -> O46-02 | E12: =IFERROR(__xludf.DUMMYFUNCTION("""COMPUTED_VALUE"""),0.0) -> 0 | I12: =IFERROR(__xludf.DUMMYFUNCTION("""COMPUTED_VALUE"""),"18-46-0 DAP") -> 18-46-0 DAP | L12: =IFERROR(__xludf.DUMMYFUNCTION("""COMPUTED_VALUE"""),4388.5212) -> 4388.5212 | M12: =IFERROR(__xludf.DUMMYFUNCTION("""COMPUTED_VALUE"""),14156.52) -> 14156.52
B13: =IFERROR(__xludf.DUMMYFUNCTION("""COMPUTED_VALUE"""),"Yellow_Corn") -> Yellow_Corn | C13: =IFERROR(__xludf.DUMMYFUNCTION("""COMPUTED_VALUE"""),"viking") -> viking | D13: =IFERROR(__xludf.DUMMYFUNCTION("""COMPUTED_VALUE"""),"O.18-06UP") -> O.18-06UP | E13: =IFERROR(__xludf.DUMMYFUNCTION("""COMPUTED_VALUE"""),198.00000000000003) -> 198 | I13: =IFERROR(__xludf.DUMMYFUNCTION("""COMPUTED_VALUE"""),"21-0-0-24s AMS Granular") -> 21-0-0-24s AMS Granular | L13: =IFERROR(__xludf.DUMMYFUNCTION("""COMPUTED_VALUE"""),9970.28064875179) -> 9970.2806 | M13: =IFERROR(__xludf.DUMMYFUNCTION("""COMPUTED_VALUE"""),7349.999999999999) -> 7350
