Workbook

Sheet Data Entry
B2: RANDY'S 2025 GRAIN TICKET ENTRY
J5: /
D6: Dates: | F6: 45978 | J6: /
D8: Farm | F8: Jones
D10: Net Weight | F10: 37560
D12: Moisture % | F12: 18
D14: Crop | F14: Organic Blue Corn
D16: Ticket Number | F16: 531-040638
D18: Notes | F18: HBT# 5314 Bob Trk# 3
D20: FM

Sheet Farms
A1: 11.5 | B1: Crop | C1: Farm | D1: Total | E1: unit | F1: Yield/AC | H1: Guarantee | I1: Coverage | J1: Claim threshhold | K1: Discount | L1: Test weight | O1: Drivers | P1: Trucks
A2: 212.6 | B2: Rye | C2: Airport | D2: =SUMIF(Data2!$B$3:$B1011,C2,Data2!$K$3:$K1011) -> 20647.5 | E2: BU | F2: =D2/A2 -> 97.119003 | G2: Conventional | I2: =sumif($C$68:$C$100,B2,$A$68:$A$100) -> 0 | J2: =H2*I2 -> 0 | K2: =sumif($C$68:$C$97,B2,$D$68:$D$97) -> 0 | L2: =sumif($C$68:$C$97,B2,$F$68:$F$97) -> 56 | O2: Randy H. | P2: 1
A3: 6.4 | B3: Rye | C3: Airport - Knilans | D3: =SUMIF(Data2!$B$3:$B1011,C3,Data2!$K$3:$K1011) -> 303.21429 | E3: BU | F3: =D3/A3 -> 47.377232 | G3: Conventional | I3: =sumif($C$68:$C$100,B3,$A$68:$A$100) -> 0 | J3: =H3*I3 -> 0 | K3: =sumif($C$68:$C$97,B3,$D$68:$D$97) -> 0 | L3: =sumif($C$68:$C$97,B3,$F$68:$F$97) -> 56
A4: 30.5 | B4: Organic Rye & VETCH | C4: Avalon Rd. | D4: =SUMIF(Data2!$B$3:$B1011,C4,Data2!$K$3:$K1011) -> 0 | E4: BU | F4: =D4/A4 -> 0 | G4: Organic | I4: =sumif($C$68:$C$100,B4,$A$68:$A$100) -> 0 | J4: =H4*I4 -> 0 | K4: =sumif($C$68:$C$97,B4,$D$68:$D$97) -> 0 | L4: =sumif($C$68:$C$97,B4,$F$68:$F$97) -> 0 | O4: Randy S. | P4: 2
A5: 28.1 | B5: Non-GMO Yellow Corn | C5: bakke | D5: =SUMIF(Data2!$B$3:$B1011,C5,Data2!$K$3:$K1011) -> 5923.7037 | E5: BU | F5: =D5/A5 -> 210.80796 | G5: Conventional | I5: =sumif($C$68:$C$100,B5,$A$68:$A$100) -> 0 | J5: =H5*I5 -> 0 | K5: =sumif($C$68:$C$97,B5,$D$68:$D$97) -> 1.5 | L5: 49 | O5: Tim | P5: 3
A6: 134.6 | B6: Hybrid Rye | C6: blue | D6: =SUMIF(Data2!$B$3:$B1011,C6,Data2!$K$3:$K1011) -> 14858.357 | E6: BU | F6: =D6/A6 -> 110.38898 | G6: Conventional | I6: =sumif($C$68:$C$100,B6,$A$68:$A$100) -> 0 | J6: =H6*I6 -> 0 | K6: 0 | L6: 51 | O6: Robert | P6: 4
A7: 5 | B7: Rye | C7: blue crop #2 | D7: =SUMIF(Data2!$B$3:$B1011,C7,Data2!$K$3:$K1011) -> 339 | E7: BU | F7: =D7/A7 -> 67.8 | G7: Conventional | I7: =sumif($C$68:$C$100,B7,$A$68:$A$100) -> 0 | J7: =H7*I7 -> 0 | K7: 0 | L7: 51
A8: 39 | B8: Lima Beans | C8: buchanon crop #1 | D8: =SUMIF(Data2!$B$3:$B1011,C8,Data2!$K$3:$K1011) -> 49.8125 | E8: Tons | F8: =D8/A8 -> 1.2772436 | G8: Conventional | I8: =sumif($C$68:$C$100,B8,$A$68:$A$100) -> 0 | J8: =H8*I8 -> 0 | K8: =sumif($C$68:$C$97,B8,$D$68:$D$97) -> 0 | L8: =sumif($C$68:$C$97,B8,$F$68:$F$97) -> 2000 | O8: Tristan | P8: 5
A9: 9.3 | B9: Enlist Soybeans | C9: buchanon crop #2 | D9: =SUMIF(Data2!$B$3:$B1011,C9,Data2!$K$3:$K1011) -> 538.91173 | E9: BU | F9: =D9/A9 -> 57.947498 | G9: Conventional | I9: =sumif($C$68:$C$100,B9,$A$68:$A$100) -> 0 | J9: =H9*I9 -> 0 | K9: 0 | L9: =sumif($C$68:$C$97,B9,$F$68:$F$97) -> 56
A10: 14 | B10: Organic Soybeans | C10: Caravilla | D10: =SUMIF(Data2!$B$3:$B1011,C10,Data2!$K$3:$K1011) -> 0 | E10: BU | F10: =D10/A10 -> 0 | G10: Organic | I10: =sumif($C$68:$C$100,B10,$A$68:$A$100) -> 0 | J10: =H10*I10 -> 0 | K10: 0 | L10: 0 | O10: Willie | P10: 63
A11: 150 | B11: 262 OR Seed beans | C11: carrol | D11: =SUMIF(Data2!$B$3:$B1011,C11,Data2!$K$3:$K1011) -> 9640.4155 | E11: BU | F11: =D11/A11 -> 64.269437 | G11: Conventional | I11: =sumif($C$68:$C$100,B11,$A$68:$A$100) -> 0 | J11: =H11*I11 -> 0 | K11: =sumif($C$68:$C$97,B11,$D$68:$D$97) -> 1.5 | L11: =sumif($C$68:$C$97,B11,$F$68:$F$97) -> 60 | O11: Julianne | P11: 41
A12: 148 | B12: Non-GMO Seed Grade Beans | C12: Cuff | D12: =SUMIF(Data2!$B$3:$B1011,C12,Data2!$K$3:$K1011) -> 10075.417 | E12: BU | F12: =D12/A12 -> 68.07714 | G12: Conventional | I12: =sumif($C$68:$C$100,B12,$A$68:$A$100) -> 0 | J12: =H12*I12 -> 0 | K12: =sumif($C$68:$C$97,B12,$D$68:$D$97) -> 1.5 | L12: =sumif($C$68:$C$97,B12,$F$68:$F$97) -> 60 | O12: Gary
A13: 12 | C13: Cullen | D13: =SUMIF(Data2!$B$3:$B1011,C13,Data2!$K$3:$K1011) -> 0 | E13: BU | F13: =D13/A13 -> 0 | G13: Organic | I13: =sumif($C$68:$C$100,B13,$A$68:$A$100) -> 0 | J13: =H13*I13 -> 0 | K13: =sumif($C$68:$C$97,B13,$D$68:$D$97) -> 0 | L13: =sumif($C$68:$C$97,B13,$F$68:$F$97) -> 0
A14: 11.9 | B14: Non-GMO Yellow Corn | C14: Daun | D14: =SUMIF(Data2!$B$3:$B1011,C14,Data2!$K$3:$K1011) -> 2004.1927 | E14: BU | F14: =D14/A14 -> 168.41955 | G14: Conventional | I14: =sumif($C$68:$C$100,B14,$A$68:$A$100) -> 0 | J14: =H14*I14 -> 0 | K14: 0 | L14: =sumif($C$68:$C$97,B14,$F$68:$F$97) -> 56
A15: 42 | B15: Non-GMO Yellow Corn | C15: delong avon | D15: =SUMIF(Data2!$B$3:$B1011,C15,Data2!$K$3:$K1011) -> 8574.1886 | E15: BU | F15: =D15/A15 -> 204.14735 | G15: Conventional | I15: =sumif($C$68:$C$100,B15,$A$68:$A$100) -> 0 | J15: =H15*I15 -> 0 | K15: =sumif($C$68:$C$97,B15,$D$68:$D$97) -> 1.5 | L15: =sumif($C$68:$C$97,B15,$F$68:$F$97) -> 56
A16: 60 | B16: Non-GMO Yellow Corn | C16: delong christopherson | D16: =SUMIF(Data2!$B$3:$B1011,C16,Data2!$K$3:$K1011) -> 14120.905 | E16: BU | F16: =D16/A16 -> 235.34842 | G16: Conventional | I16: =sumif($C$68:$C$100,B16,$A$68:$A$100) -> 0 | J16: =H16*I16 -> 0 | K16: =sumif($C$68:$C$97,B16,$D$68:$D$97) -> 1.5 | L16: =sumif($C$68:$C$97,B16,$F$68:$F$97) -> 56
A17: 56.9 | B17: Non-GMO Yellow Corn | C17: delong meyer | D17: =SUMIF(Data2!$B$3:$B1011,C17,Data2!$K$3:$K1011) -> 14510.575 | E17: BU | F17: =D17/A17 -> 255.0189 | G17: Conventional | I17: =sumif($C$68:$C$100,B17,$A$68:$A$100) -> 0 | J17: =H17*I17 -> 0 | K17: 1.5 | L17: =sumif($C$68:$C$97,B17,$F$68:$F$97) -> 56
A18: 69 | B18: Lima Beans | C18: elwoods | D18: =SUMIF(Data2!$B$3:$B1011,C18,Data2!$K$3:$K1011) -> 148.24 | E18: Tons | F18: =D18/A18 -> 2.1484058 | G18: Conventional | I18: =sumif($C$68:$C$100,B18,$A$68:$A$100) -> 0 | J18: =H18*I18 -> 0 | K18: =sumif($C$68:$C$97,B18,$D$68:$D$97) -> 0 | L18: =sumif($C$68:$C$97,B18,$F$68:$F$97) -> 2000
A19: 10.9 | B19: Enlist Soybeans | C19: fagan | D19: =SUMIF(Data2!$B$3:$B1011,C19,Data2!$K$3:$K1011) -> 800.97543 | E19: BU | F19: =D19/A19 -> 73.483984 | G19: Conventional | I19: =sumif($C$68:$C$100,B19,$A$68:$A$100) -> 0 | J19: =H19*I19 -> 0 | K19: =sumif($C$68:$C$97,B19,$D$68:$D$97) -> 1.4 | L19: =sumif($C$68:$C$97,B19,$F$68:$F$97) -> 56
A20: 116 | B20: Organic Soybeans | C20: Fletcher Cribben | D20: =SUMIF(Data2!$B$3:$B1011,C20,Data2!$K$3:$K1011) -> 0 | E20: BU | F20: =D20/A20 -> 0 | G20: Organic | I20: =sumif($C$68:$C$100,B20,$A$68:$A$100) -> 0 | J20: =H20*I20 -> 0 | K20: 1.01 | L20: =sumif($C$68:$C$97,B20,$F$68:$F$97) -> 60
A21: 9 | B21: Enlist Soybeans | C21: fox den | D21: =SUMIF(Data2!$B$3:$B1011,C21,Data2!$K$3:$K1011) -> 571.535 | E21: BU | F21: =D21/A21 -> 63.503889 | G21: Conventional | I21: =sumif($C$68:$C$100,B21,$A$68:$A$100) -> 0 | J21: =H21*I21 -> 0 | K21: =sumif($C$68:$C$97,B21,$D$68:$D$97) -> 1.4 | L21: =sumif($C$68:$C$97,B21,$F$68:$F$97) -> 56
A22: 40 | B22: Hybrid Rye | C22: fox kettle | D22: =SUMIF(Data2!$B$3:$B1011,C22,Data2!$K$3:$K1011) -> 4141.4732 | E22: BU | F22: =D22/A22 -> 103.53683 | G22: Conventional | I22: =sumif($C$68:$C$100,B22,$A$68:$A$100) -> 0 | J22: =H22*I22 -> 0 | K22: =sumif($C$68:$C$97,B22,$D$68:$D$97) -> 0 | L22: 60
A23: 8.8 | B23: Non-GMO Yellow Corn | C23: fox kettle little | D23: =SUMIF(Data2!$B$3:$B1011,C23,Data2!$K$3:$K1011) -> 1799.7942 | E23: BU | F23: =D23/A23 -> 204.52207 | G23: Conventional | I23: =sumif($C$68:$C$100,B23,$A$68:$A$100) -> 0 | J23: =H23*I23 -> 0 | K23: 0 | L23: 60
A24: 14 | B24: Enlist Soybeans | C24: fox lemans | D24: =SUMIF(Data2!$B$3:$B1011,C24,Data2!$K$3:$K1011) -> 1068.4131 | E24: BU | F24: =D24/A24 -> 76.315219 | G24: Conventional | I24: =sumif($C$68:$C$100,B24,$A$68:$A$100) -> 0 | J24: =H24*I24 -> 0 | K24: =sumif($C$68:$C$97,B24,$D$68:$D$97) -> 1.4 | L24: 11
A25: 196.3 | B25: Non-GMO Yellow Corn | C25: gessley | D25: =SUMIF(Data2!$B$3:$B1011,C25,Data2!$K$3:$K1011) -> 45374.837 | E25: BU | F25: =D25/A25 -> 231.15047 | G25: Conventional | I25: =sumif($C$68:$C$100,B25,$A$68:$A$100) -> 0 | J25: =H25*I25 -> 0 | K25: =sumif($C$68:$C$97,B25,$D$68:$D$97) -> 1.5 | L25: =sumif($C$68:$C$97,B25,$F$68:$F$97) -> 56
A26: 104 | B26: Organic Sweet Corn | C26: Goat Pasture | D26: =sumif(Data2!$B$3:$B1011,C26,Data2!$K$3:$K1011) -> 137.87 | E26: Tons | F26: =D26/A26 -> 1.3256731 | G26: Organic | I26: =sumif($C$68:$C$100,B26,$A$68:$A$100) -> 0 | J26: =H26*I26 -> 0 | K26: =sumif($C$68:$C$97,B26,$D$68:$D$97) -> 0 | L26: =sumif($C$68:$C$97,B26,$F$68:$F$97) -> 2000
A27: 362.1 | B27: Non-GMO Yellow Corn | C27: Gessert | D27: =SUMIF(Data2!$B$3:$B1011,C27,Data2!$K$3:$K1011) -> 81039.561 | E27: BU | F27: =D27/A27 -> 223.80437 | G27: Conventional | I27: =sumif($C$68:$C$100,B27,$A$68:$A$100) -> 0 | J27: =H27*I27 -> 0 | K27: =sumif($C$68:$C$97,B27,$D$68:$D$97) -> 1.5 | L27: =sumif($C$68:$C$97,B27,$F$68:$F$97) -> 56
A28: 73.7 | B28: Non-GMO Yellow Corn | C28: hoff | D28: =SUMIF(Data2!$B$3:$B1011,C28,Data2!$K$3:$K1011) -> 14534.192 | E28: BU | F28: =D28/A28 -> 197.20749 | G28: Conventional | I28: =sumif($C$68:$C$100,B28,$A$68:$A$100) -> 0 | J28: =H28*I28 -> 0 | K28: =sumif($C$68:$C$97,B28,$D$68:$D$97) -> 1.5 | L28: =sumif($C$68:$C$97,B28,$F$68:$F$97) -> 56
A29: 37.6 | B29: Non-GMO Yellow Corn | C29: home | D29: =SUMIF(Data2!$B$3:$B1011,C29,Data2!$K$3:$K1011) -> 9653.6101 | E29: BU | F29: =D29/A29 -> 256.74495 | G29: Conventional | I29: =sumif($C$68:$C$100,B29,$A$68:$A$100) -> 0 | J29: =H29*I29 -> 0 | K29: =sumif($C$68:$C$97,B29,$D$68:$D$97) -> 1.5 | L29: =sumif($C$68:$C$97,B29,$F$68:$F$97) -> 56
A30: 154.9 | B30: Non-GMO Yellow Corn | C30: inman | D30: =SUMIF(Data2!$B$3:$B1011,C30,Data2!$K$3:$K1011) -> 32410.974 | E30: BU | F30: =D30/A30 -> 209.23805 | G30: Conventional | I30: =sumif($C$68:$C$100,B30,$A$68:$A$100) -> 0 | J30: =H30*I30 -> 0 | K30: =sumif($C$68:$C$97,B30,$D$68:$D$97) -> 1.5 | L30: =sumif($C$68:$C$97,B30,$F$68:$F$97) -> 56
A31: 48.1 | B31: Non-GMO Yellow Corn | C31: Inman, Brads | D31: =SUMIF(Data2!$B$3:$B1011,C31,Data2!$K$3:$K1011) -> 7877.0134 | E31: BU | F31: =D31/A31 -> 163.76327 | G31: Conventional | I31: =sumif($C$68:$C$100,B31,$A$68:$A$100) -> 0 | J31: =H31*I31 -> 0 | K31: =sumif($C$68:$C$97,B31,$D$68:$D$97) -> 1.5 | L31: =sumif($C$68:$C$97,B31,$F$68:$F$97) -> 56
A32: 22.8 | B32: Enlist Soybeans | C32: jehovah crop | D32: =SUMIF(Data2!$B$3:$B1011,C32,Data2!$K$3:$K1011) -> 1628.0586 | E32: BU | F32: =D32/A32 -> 71.406078 | G32: Conventional | I32: =sumif($C$68:$C$100,B32,$A$68:$A$100) -> 0 | J32: =H32*I32 -> 0 | K32: =sumif($C$68:$C$97,B32,$D$68:$D$97) -> 1.4 | L32: =sumif($C$68:$C$97,B32,$F$68:$F$97) -> 56
A33: 92.25 | B33: Organic Blue Corn | C33: Jones | D33: =SUMIF(Data2!$B$3:$B1011,C33,Data2!$K$3:$K1011) -> 0 | E33: BU | F33: =D33/A33 -> 0 | G33: Organic | I33: =sumif($C$68:$C$100,B33,$A$68:$A$100) -> 0 | J33: =H33*I33 -> 0 | K33: =sumif($C$68:$C$97,B33,$D$68:$D$97) -> 1.5 | L33: =sumif($C$68:$C$97,B33,$F$68:$F$97) -> 56
A34: 91 | B34: Organic Peas | C34: Kopp East Crop #1 | D34: =SUMIF(Data2!$B$3:$B1011,C34,Data2!$K$3:$K1011) -> 4323.4844 | E34: BU | F34: =D34/A34 -> 47.510817 | G34: Organic | I34: =sumif($C$68:$C$100,B34,$A$68:$A$100) -> 0 | J34: =H34*I34 -> 0 | K34: 1.5 | L34: 56
A35: 124 | B35: Organic Peas | C35: Kopp West Crop #1 | D35: =SUMIF(Data2!$B$3:$B1011,C35,Data2!$K$3:$K1011) -> 13387.719 | E35: BU | F35: =D35/A35 -> 107.96547 | G35: Organic | I35: =sumif($C$68:$C$100,B35,$A$68:$A$100) -> 0 | J35: =H35*I35 -> 0 | K35: 1.5 | L35: 56
A36: 21 | B36: Organic Snap Beans | C36: Kopp East Crop #2-1 | D36: =SUMIF(Data2!$B$3:$B1011,C36,Data2!$K$3:$K1011) -> 4450.5781 | E36: BU | F36: =D36/A36 -> 211.93229 | G36: Organic | I36: =sumif($C$68:$C$100,B36,$A$68:$A$100) -> 0 | J36: =H36*I36 -> 0 | K36: 1.5 | L36: 56
A37: 63 | B37: Organic Snap Beans | C37: Kopp East Crop #2-2 | D37: =SUMIF(Data2!$B$3:$B1011,C37,Data2!$K$3:$K1011) -> 14279.672 | E37: BU | F37: =D37/A37 -> 226.66146 | G37: Organic
A38: 124 | B38: Organic Snap Beans | C38: Kopp West Crop #2 | D38: =SUMIF(Data2!$B$3:$B1011,C38,Data2!$K$3:$K1011) -> 27172.031 | E38: BU | F38: =D38/A38 -> 219.12928 | G38: Organic | I38: =sumif($C$68:$C$100,B38,$A$68:$A$100) -> 0 | J38: =H38*I38 -> 0 | K38: 1.5 | L38: 56
A39: 214 | B39: Non-GMO Yellow Corn | C39: Klug North | D39: =SUMIF(Data2!$B$3:$B1011,C39,Data2!$K$3:$K1011) -> 45867.709 | E39: BU | F39: =D39/A39 -> 214.33509 | G39: Conventional | I39: =sumif($C$68:$C$100,B39,$A$68:$A$100) -> 0 | J39: =H39*I39 -> 0 | K39: 1.5 | L39: 56
A40: 18.2 | B40: Non-GMO Yellow Corn | C40: lake | D40: =SUMIF(Data2!$B$3:$B1011,C40,Data2!$K$3:$K1011) -> 3769.9924 | E40: BU | F40: =D40/A40 -> 207.14244 | G40: Conventional | I40: =sumif($C$68:$C$100,B41,$A$68:$A$100) -> 0 | J40: =H40*I40 -> 0 | K40: 1.5 | L40: 56
...

Sheet Data2
A1: =IFERROR(__xludf.DUMMYFUNCTION("IMPORTRANGE(""https://docs.google.com/spreadsheets/d/1d1umGcBflAvJSG85XbMDFWFB-r8uNyLx1DnkM26F2W8/edit?gid=1414208589#gid=1414208589"",""Data!A1:H"")"),"Date") -> Date | B1: =IFERROR(__xludf.DUMMYFUNCTION("""COMPUTED_VALUE"""),"FARM") -> FARM | C1: =IFERROR(__xludf.DUMMYFUNCTION("""COMPUTED_VALUE"""),"NET WEIGHT") -> NET WEIGHT | D1: =IFERROR(__xludf.DUMMYFUNCTION("""COMPUTED_VALUE"""),"MOISTURE") -> MOISTURE | E1: =IFERROR(__xludf.DUMMYFUNCTION("""COMPUTED_VALUE"""),"CROP") -> CROP | F1: =IFERROR(__xludf.DUMMYFUNCTION("""COMPUTED_VALUE"""),"TICKET NO.") -> TICKET NO. | G1: =IFERROR(__xludf.DUMMYFUNCTION("""COMPUTED_VALUE"""),"NOTES") -> NOTES | H1: =IFERROR(__xludf.DUMMYFUNCTION("""COMPUTED_VALUE"""),"FM") -> FM | I1: FM Discount Factor | J1: GROSS BU | K1: NET BU IF SOLD | L1: Discount | M1: Test Weight | N1: Moisture Shrink
A2: =IFERROR(__xludf.DUMMYFUNCTION("""COMPUTED_VALUE"""),45860.0) -> 45860 | B2: =IFERROR(__xludf.DUMMYFUNCTION("""COMPUTED_VALUE"""),"Airport") -> Airport | C2: =IFERROR(__xludf.DUMMYFUNCTION("""COMPUTED_VALUE"""),55480.0) -> 55480 | D2: =IFERROR(__xludf.DUMMYFUNCTION("""COMPUTED_VALUE"""),12.9) -> 12.9 | E2: =IFERROR(__xludf.DUMMYFUNCTION("""COMPUTED_VALUE"""),"Rye ") -> Rye | F2: =IFERROR(__xludf.DUMMYFUNCTION("""COMPUTED_VALUE"""),"H066666") -> H066666 | G2: =IFERROR(__xludf.DUMMYFUNCTION("""COMPUTED_VALUE"""),"HBT# 5652 WR Trk# 41") -> HBT# 5652 WR Trk# 41 | H2: =IFERROR(__xludf.DUMMYFUNCTION("""COMPUTED_VALUE"""),0.1) -> 0.1 | I2: =if(H2>=1,H2-1,"0")/100 -> 0 | J2: =(((100-((D2-N2)*L2))*(C2))/M2)/100 -> 990.71429 | K2: =J2*(1-I2) -> 990.71429 | L2: =sumif(Farms!$C$68:$C$104,E1,Farms!$D$68:$D$104) -> 0 | M2: 56 | N2: =sumif(Farms!$C$68:$C$104,E1,Farms!$G$68:$G$104) -> 0
A3: =IFERROR(__xludf.DUMMYFUNCTION("""COMPUTED_VALUE"""),45860.0) -> 45860 | B3: =IFERROR(__xludf.DUMMYFUNCTION("""COMPUTED_VALUE"""),"Airport") -> Airport | C3: =IFERROR(__xludf.DUMMYFUNCTION("""COMPUTED_VALUE"""),42780.0) -> 42780 | D3: =IFERROR(__xludf.DUMMYFUNCTION("""COMPUTED_VALUE"""),13.5) -> 13.5 | E3: =IFERROR(__xludf.DUMMYFUNCTION("""COMPUTED_VALUE"""),"Rye ") -> Rye | F3: =IFERROR(__xludf.DUMMYFUNCTION("""COMPUTED_VALUE"""),"H066668") -> H066668 | G3: =IFERROR(__xludf.DUMMYFUNCTION("""COMPUTED_VALUE"""),"HBT# 3122 Bob Trk# 5") -> HBT# 3122 Bob Trk# 5 | H3: =IFERROR(__xludf.DUMMYFUNCTION("""COMPUTED_VALUE"""),0.2) -> 0.2 | I3: =if(H3>=1,H3-1,"0")/100 -> 0 | J3: =(((100-((D3-N3)*L3))*(C3))/M3)/100 -> 763.92857 | K3: =J3*(1-I3) -> 763.92857 | L3: =sumif(Farms!$C$68:$C$104,E3,Farms!$D$68:$D$104) -> 0 | M3: 56 | N3: 0
A4: =IFERROR(__xludf.DUMMYFUNCTION("""COMPUTED_VALUE"""),45866.0) -> 45866 | B4: =IFERROR(__xludf.DUMMYFUNCTION("""COMPUTED_VALUE"""),"Airport") -> Airport | C4: =IFERROR(__xludf.DUMMYFUNCTION("""COMPUTED_VALUE"""),56480.0) -> 56480 | D4: =IFERROR(__xludf.DUMMYFUNCTION("""COMPUTED_VALUE"""),12.5) -> 12.5 | E4: =IFERROR(__xludf.DUMMYFUNCTION("""COMPUTED_VALUE"""),"Rye ") -> Rye | F4: =IFERROR(__xludf.DUMMYFUNCTION("""COMPUTED_VALUE"""),"H066671") -> H066671 | G4: =IFERROR(__xludf.DUMMYFUNCTION("""COMPUTED_VALUE"""),"HBT# 4558 Bob Trk# 63") -> HBT# 4558 Bob Trk# 63 | H4: =IFERROR(__xludf.DUMMYFUNCTION("""COMPUTED_VALUE"""),0.1) -> 0.1 | I4: =if(H4>=1,H4-1,"0")/100 -> 0 | J4: =(((100-((D4-N4)*L4))*(C4))/M4)/100 -> 1008.5714 | K4: =J4*(1-I4) -> 1008.5714 | L4: =sumif(Farms!$C$68:$C$104,E4,Farms!$D$68:$D$104) -> 0 | M4: 56 | N4: 0
A5: =IFERROR(__xludf.DUMMYFUNCTION("""COMPUTED_VALUE"""),45866.0) -> 45866 | B5: =IFERROR(__xludf.DUMMYFUNCTION("""COMPUTED_VALUE"""),"Airport") -> Airport | C5: =IFERROR(__xludf.DUMMYFUNCTION("""COMPUTED_VALUE"""),54480.0) -> 54480 | D5: =IFERROR(__xludf.DUMMYFUNCTION("""COMPUTED_VALUE"""),11.9) -> 11.9 | E5: =IFERROR(__xludf.DUMMYFUNCTION("""COMPUTED_VALUE"""),"Rye ") -> Rye | F5: =IFERROR(__xludf.DUMMYFUNCTION("""COMPUTED_VALUE"""),"H066672") -> H066672 | G5: =IFERROR(__xludf.DUMMYFUNCTION("""COMPUTED_VALUE"""),"HBT# 5653 WR Trk# 41") -> HBT# 5653 WR Trk# 41 | H5: =IFERROR(__xludf.DUMMYFUNCTION("""COMPUTED_VALUE"""),0.2) -> 0.2 | I5: =if(H5>=1,H5-1,"0")/100 -> 0 | J5: =(((100-((D5-N5)*L5))*(C5))/M5)/100 -> 972.85714 | K5: =J5*(1-I5) -> 972.85714 | L5: =sumif(Farms!$C$68:$C$104,E5,Farms!$D$68:$D$104) -> 0 | M5: 56 | N5: 0
A6: =IFERROR(__xludf.DUMMYFUNCTION("""COMPUTED_VALUE"""),45866.0) -> 45866 | B6: =IFERROR(__xludf.DUMMYFUNCTION("""COMPUTED_VALUE"""),"Airport") -> Airport | C6: =IFERROR(__xludf.DUMMYFUNCTION("""COMPUTED_VALUE"""),57020.0) -> 57020 | D6: =IFERROR(__xludf.DUMMYFUNCTION("""COMPUTED_VALUE"""),12.0) -> 12 | E6: =IFERROR(__xludf.DUMMYFUNCTION("""COMPUTED_VALUE"""),"Rye ") -> Rye | F6: =IFERROR(__xludf.DUMMYFUNCTION("""COMPUTED_VALUE"""),"H066673") -> H066673 | G6: =IFERROR(__xludf.DUMMYFUNCTION("""COMPUTED_VALUE"""),"HBT# 3124 Bob Trk# 5") -> HBT# 3124 Bob Trk# 5 | H6: =IFERROR(__xludf.DUMMYFUNCTION("""COMPUTED_VALUE"""),0.19) -> 0.19 | I6: =if(H6>=1,H6-1,"0")/100 -> 0 | J6: =(((100-((D6-N6)*L6))*(C6))/M6)/100 -> 1018.2143 | K6: =J6*(1-I6) -> 1018.2143 | L6: =sumif(Farms!$C$68:$C$104,E6,Farms!$D$68:$D$104) -> 0 | M6: 56 | N6: 0
A7: =IFERROR(__xludf.DUMMYFUNCTION("""COMPUTED_VALUE"""),45868.0) -> 45868 | B7: =IFERROR(__xludf.DUMMYFUNCTION("""COMPUTED_VALUE"""),"Airport") -> Airport | C7: =IFERROR(__xludf.DUMMYFUNCTION("""COMPUTED_VALUE"""),55540.0) -> 55540 | D7: =IFERROR(__xludf.DUMMYFUNCTION("""COMPUTED_VALUE"""),13.0) -> 13 | E7: =IFERROR(__xludf.DUMMYFUNCTION("""COMPUTED_VALUE"""),"Rye ") -> Rye | F7: =IFERROR(__xludf.DUMMYFUNCTION("""COMPUTED_VALUE"""),"H066675") -> H066675 | G7: =IFERROR(__xludf.DUMMYFUNCTION("""COMPUTED_VALUE"""),"HBT# 3125 Julianne Trk# 5") -> HBT# 3125 Julianne Trk# 5 | H7: =IFERROR(__xludf.DUMMYFUNCTION("""COMPUTED_VALUE"""),0.1) -> 0.1 | I7: =if(H7>=1,H7-1,"0")/100 -> 0 | J7: =(((100-((D7-N7)*L7))*(C7))/M7)/100 -> 991.78571 | K7: =J7*(1-I7) -> 991.78571 | L7: =sumif(Farms!$C$68:$C$104,E7,Farms!$D$68:$D$104) -> 0 | M7: 56 | N7: 0
A8: =IFERROR(__xludf.DUMMYFUNCTION("""COMPUTED_VALUE"""),45868.0) -> 45868 | B8: =IFERROR(__xludf.DUMMYFUNCTION("""COMPUTED_VALUE"""),"Airport") -> Airport | C8: =IFERROR(__xludf.DUMMYFUNCTION("""COMPUTED_VALUE"""),55440.0) -> 55440 | D8: =IFERROR(__xludf.DUMMYFUNCTION("""COMPUTED_VALUE"""),13.1) -> 13.1 | E8: =IFERROR(__xludf.DUMMYFUNCTION("""COMPUTED_VALUE"""),"Rye ") -> Rye | F8: =IFERROR(__xludf.DUMMYFUNCTION("""COMPUTED_VALUE"""),"H066676") -> H066676 | G8: =IFERROR(__xludf.DUMMYFUNCTION("""COMPUTED_VALUE"""),"HBT# 5515 WR Trk# 5") -> HBT# 5515 WR Trk# 5 | H8: =IFERROR(__xludf.DUMMYFUNCTION("""COMPUTED_VALUE"""),0.2) -> 0.2 | I8: =if(H8>=1,H8-1,"0")/100 -> 0 | J8: =(((100-((D8-N8)*L8))*(C8))/M8)/100 -> 990 | K8: =J8*(1-I8) -> 990 | L8: =sumif(Farms!$C$68:$C$104,E8,Farms!$D$68:$D$104) -> 0 | M8: 56 | N8: 0
A9: =IFERROR(__xludf.DUMMYFUNCTION("""COMPUTED_VALUE"""),45868.0) -> 45868 | B9: =IFERROR(__xludf.DUMMYFUNCTION("""COMPUTED_VALUE"""),"Airport") -> Airport | C9: =IFERROR(__xludf.DUMMYFUNCTION("""COMPUTED_VALUE"""),51340.0) -> 51340 | D9: =IFERROR(__xludf.DUMMYFUNCTION("""COMPUTED_VALUE"""),13.8) -> 13.8 | E9: =IFERROR(__xludf.DUMMYFUNCTION("""COMPUTED_VALUE"""),"Rye ") -> Rye | F9: =IFERROR(__xludf.DUMMYFUNCTION("""COMPUTED_VALUE"""),"H066677") -> H066677 | G9: =IFERROR(__xludf.DUMMYFUNCTION("""COMPUTED_VALUE"""),"HBT# 4559 Gary Trk#63") -> HBT# 4559 Gary Trk#63 | H9: =IFERROR(__xludf.DUMMYFUNCTION("""COMPUTED_VALUE"""),0.1) -> 0.1 | I9: =if(H9>=1,H9-1,"0")/100 -> 0 | J9: =(((100-((D9-N9)*L9))*(C9))/M9)/100 -> 916.78571 | K9: =J9*(1-I9) -> 916.78571 | L9: =sumif(Farms!$C$68:$C$104,E9,Farms!$D$68:$D$104) -> 0 | M9: 56 | N9: 0
A10: =IFERROR(__xludf.DUMMYFUNCTION("""COMPUTED_VALUE"""),45868.0) -> 45868 | B10: =IFERROR(__xludf.DUMMYFUNCTION("""COMPUTED_VALUE"""),"Airport") -> Airport | C10: =IFERROR(__xludf.DUMMYFUNCTION("""COMPUTED_VALUE"""),53960.0) -> 53960 | D10: =IFERROR(__xludf.DUMMYFUNCTION("""COMPUTED_VALUE"""),13.6) -> 13.6 | E10: =IFERROR(__xludf.DUMMYFUNCTION("""COMPUTED_VALUE"""),"Rye ") -> Rye | F10: =IFERROR(__xludf.DUMMYFUNCTION("""COMPUTED_VALUE"""),"H066679") -> H066679 | G10: =IFERROR(__xludf.DUMMYFUNCTION("""COMPUTED_VALUE"""),"HBT# 5654 Gary Trk# 41") -> HBT# 5654 Gary Trk# 41 | H10: =IFERROR(__xludf.DUMMYFUNCTION("""COMPUTED_VALUE"""),0.1) -> 0.1 | I10: =if(H10>=1,H10-1,"0")/100 -> 0 | J10: =(((100-((D10-N10)*L10))*(C10))/M10)/100 -> 963.57143 | K10: =J10*(1-I10) -> 963.57143 | L10: =sumif(Farms!$C$68:$C$104,E10,Farms!$D$68:$D$104) -> 0 | M10: 56 | N10: 0
A11: =IFERROR(__xludf.DUMMYFUNCTION("""COMPUTED_VALUE"""),45873.0) -> 45873 | B11: =IFERROR(__xludf.DUMMYFUNCTION("""COMPUTED_VALUE"""),"Airport") -> Airport | C11: =IFERROR(__xludf.DUMMYFUNCTION("""COMPUTED_VALUE"""),59780.0) -> 59780 | D11: =IFERROR(__xludf.DUMMYFUNCTION("""COMPUTED_VALUE"""),13.0) -> 13 | E11: =IFERROR(__xludf.DUMMYFUNCTION("""COMPUTED_VALUE"""),"Rye ") -> Rye | F11: =IFERROR(__xludf.DUMMYFUNCTION("""COMPUTED_VALUE"""),"H066689") -> H066689 | G11: =IFERROR(__xludf.DUMMYFUNCTION("""COMPUTED_VALUE"""),"HBT# 3126 Julianne Trk# 5") -> HBT# 3126 Julianne Trk# 5 | H11: =IFERROR(__xludf.DUMMYFUNCTION("""COMPUTED_VALUE"""),0.2) -> 0.2 | I11: =if(H11>=1,H11-1,"0")/100 -> 0 | J11: =(((100-((D11-N11)*L11))*(C11))/M11)/100 -> 1067.5 | K11: =J11*(1-I11) -> 1067.5 | L11: =sumif(Farms!$C$68:$C$104,E11,Farms!$D$68:$D$104) -> 0 | M11: 56 | N11: 0
A12: =IFERROR(__xludf.DUMMYFUNCTION("""COMPUTED_VALUE"""),45873.0) -> 45873 | B12: =IFERROR(__xludf.DUMMYFUNCTION("""COMPUTED_VALUE"""),"Airport") -> Airport | C12: =IFERROR(__xludf.DUMMYFUNCTION("""COMPUTED_VALUE"""),48520.0) -> 48520 | D12: =IFERROR(__xludf.DUMMYFUNCTION("""COMPUTED_VALUE"""),12.3) -> 12.3 | E12: =IFERROR(__xludf.DUMMYFUNCTION("""COMPUTED_VALUE"""),"Rye ") -> Rye | F12: =IFERROR(__xludf.DUMMYFUNCTION("""COMPUTED_VALUE"""),"H066690") -> H066690 | G12: =IFERROR(__xludf.DUMMYFUNCTION("""COMPUTED_VALUE"""),"HBT# 4560 Bob Trk# 63") -> HBT# 4560 Bob Trk# 63 | H12: =IFERROR(__xludf.DUMMYFUNCTION("""COMPUTED_VALUE"""),0.1) -> 0.1 | I12: =if(H12>=1,H12-1,"0")/100 -> 0 | J12: =(((100-((D12-N12)*L12))*(C12))/M12)/100 -> 866.42857 | K12: =J12*(1-I12) -> 866.42857 | L12: =sumif(Farms!$C$68:$C$104,E12,Farms!$D$68:$D$104) -> 0 | M12: 56 | N12: 0
A13: =IFERROR(__xludf.DUMMYFUNCTION("""COMPUTED_VALUE"""),45873.0) -> 45873 | B13: =IFERROR(__xludf.DUMMYFUNCTION("""COMPUTED_VALUE"""),"Airport") -> Airport | C13: =IFERROR(__xludf.DUMMYFUNCTION("""COMPUTED_VALUE"""),57760.0) -> 57760 | D13: =IFERROR(__xludf.DUMMYFUNCTION("""COMPUTED_VALUE"""),12.9) -> 12.9 | E13: =IFERROR(__xludf.DUMMYFUNCTION("""COMPUTED_VALUE"""),"Rye ") -> Rye | F13: =IFERROR(__xludf.DUMMYFUNCTION("""COMPUTED_VALUE"""),"H066691") -> H066691 | G13: =IFERROR(__xludf.DUMMYFUNCTION("""COMPUTED_VALUE"""),"HBT# 5516 Tanner Trk# 2") -> HBT# 5516 Tanner Trk# 2 | H13: =IFERROR(__xludf.DUMMYFUNCTION("""COMPUTED_VALUE"""),0.2) -> 0.2 | I13: =if(H13>=1,H13-1,"0")/100 -> 0 | J13: =(((100-((D13-N13)*L13))*(C13))/M13)/100 -> 1031.4286 | K13: =J13*(1-I13) -> 1031.4286 | L13: =sumif(Farms!$C$68:$C$104,E13,Farms!$D$68:$D$104) -> 0 | M13: 56 | N13: 0
A14: =IFERROR(__xludf.DUMMYFUNCTION("""COMPUTED_VALUE"""),45873.0) -> 45873 | B14: =IFERROR(__xludf.DUMMYFUNCTION("""COMPUTED_VALUE"""),"Airport") -> Airport | C14: =IFERROR(__xludf.DUMMYFUNCTION("""COMPUTED_VALUE"""),56400.0) -> 56400 | D14: =IFERROR(__xludf.DUMMYFUNCTION("""COMPUTED_VALUE"""),12.0) -> 12 | E14: =IFERROR(__xludf.DUMMYFUNCTION("""COMPUTED_VALUE"""),"Rye ") -> Rye | F14: =IFERROR(__xludf.DUMMYFUNCTION("""COMPUTED_VALUE"""),"H066693") -> H066693 | G14: =IFERROR(__xludf.DUMMYFUNCTION("""COMPUTED_VALUE"""),"HBT# 4561 Bob Trk# 63") -> HBT# 4561 Bob Trk# 63 | H14: =IFERROR(__xludf.DUMMYFUNCTION("""COMPUTED_VALUE"""),0.1) -> 0.1 | I14: =if(H14>=1,H14-1,"0")/100 -> 0 | J14: =(((100-((D14-N14)*L14))*(C14))/M14)/100 -> 1007.1429 | K14: =J14*(1-I14) -> 1007.1429 | L14: =sumif(Farms!$C$68:$C$104,E14,Farms!$D$68:$D$104) -> 0 | M14: =sumif(Farms!$C$68:$C$104,E14,Farms!$F$68:$F$104) -> 56 | N14: =sumif(Farms!$C$68:$C$104,E14,Farms!$G$68:$G$104) -> 13
A15: =IFERROR(__xludf.DUMMYFUNCTION("""COMPUTED_VALUE"""),45874.0) -> 45874 | B15: =IFERROR(__xludf.DUMMYFUNCTION("""COMPUTED_VALUE"""),"Airport") -> Airport | C15: =IFERROR(__xludf.DUMMYFUNCTION("""COMPUTED_VALUE"""),57040.0) -> 57040 | D15: =IFERROR(__xludf.DUMMYFUNCTION("""COMPUTED_VALUE"""),14.3) -> 14.3 | E15: =IFERROR(__xludf.DUMMYFUNCTION("""COMPUTED_VALUE"""),"Rye ") -> Rye | F15: =IFERROR(__xludf.DUMMYFUNCTION("""COMPUTED_VALUE"""),"H066694") -> H066694 | G15: =IFERROR(__xludf.DUMMYFUNCTION("""COMPUTED_VALUE"""),"HBT# 4562 Bob Trk# 63") -> HBT# 4562 Bob Trk# 63 | H15: =IFERROR(__xludf.DUMMYFUNCTION("""COMPUTED_VALUE"""),0.3) -> 0.3 | I15: =if(H15>=1,H15-1,"0")/100 -> 0 | J15: =(((100-((D15-N15)*L15))*(C15))/M15)/100 -> 1018.5714 | K15: =J15*(1-I15) -> 1018.5714 | L15: =sumif(Farms!$C$68:$C$104,E15,Farms!$D$68:$D$104) -> 0 | M15: =sumif(Farms!$C$68:$C$104,E15,Farms!$F$68:$F$104) -> 56 | N15: =sumif(Farms!$C$68:$C$104,E15,Farms!$G$68:$G$104) -> 13
A16: =IFERROR(__xludf.DUMMYFUNCTION("""COMPUTED_VALUE"""),45874.0) -> 45874 | B16: =IFERROR(__xludf.DUMMYFUNCTION("""COMPUTED_VALUE"""),"Airport") -> Airport | C16: =IFERROR(__xludf.DUMMYFUNCTION("""COMPUTED_VALUE"""),56960.0) -> 56960 | D16: =IFERROR(__xludf.DUMMYFUNCTION("""COMPUTED_VALUE"""),13.0) -> 13 | E16: =IFERROR(__xludf.DUMMYFUNCTION("""COMPUTED_VALUE"""),"Rye ") -> Rye | F16: =IFERROR(__xludf.DUMMYFUNCTION("""COMPUTED_VALUE"""),"H066695") -> H066695 | G16: =IFERROR(__xludf.DUMMYFUNCTION("""COMPUTED_VALUE"""),"HBT# 4563 Bob Trk# 63") -> HBT# 4563 Bob Trk# 63 | H16: =IFERROR(__xludf.DUMMYFUNCTION("""COMPUTED_VALUE"""),0.4) -> 0.4 | I16: =if(H16>=1,H16-1,"0")/100 -> 0 | J16: =(((100-((D16-N16)*L16))*(C16))/M16)/100 -> 1017.1429 | K16: =J16*(1-I16) -> 1017.1429 | L16: =sumif(Farms!$C$68:$C$104,E16,Farms!$D$68:$D$104) -> 0 | M16: =sumif(Farms!$C$68:$C$104,E16,Farms!$F$68:$F$104) -> 56 | N16: =sumif(Farms!$C$68:$C$104,E16,Farms!$G$68:$G$104) -> 13
A17: =IFERROR(__xludf.DUMMYFUNCTION("""COMPUTED_VALUE"""),45874.0) -> 45874 | B17: =IFERROR(__xludf.DUMMYFUNCTION("""COMPUTED_VALUE"""),"Airport") -> Airport | C17: =IFERROR(__xludf.DUMMYFUNCTION("""COMPUTED_VALUE"""),55100.0) -> 55100 | D17: =IFERROR(__xludf.DUMMYFUNCTION("""COMPUTED_VALUE"""),12.6) -> 12.6 | E17: =IFERROR(__xludf.DUMMYFUNCTION("""COMPUTED_VALUE"""),"Rye ") -> Rye | F17: =IFERROR(__xludf.DUMMYFUNCTION("""COMPUTED_VALUE"""),"H066696") -> H066696 | G17: =IFERROR(__xludf.DUMMYFUNCTION("""COMPUTED_VALUE"""),"HBT# 5517 Tanner Trk# 2") -> HBT# 5517 Tanner Trk# 2 | H17: =IFERROR(__xludf.DUMMYFUNCTION("""COMPUTED_VALUE"""),0.2) -> 0.2 | I17: =if(H17>=1,H17-1,"0")/100 -> 0 | J17: =(((100-((D17-N17)*L17))*(C17))/M17)/100 -> 983.92857 | K17: =J17*(1-I17) -> 983.92857 | L17: =sumif(Farms!$C$68:$C$104,E17,Farms!$D$68:$D$104) -> 0 | M17: =sumif(Farms!$C$68:$C$104,E17,Farms!$F$68:$F$104) -> 56 | N17: =sumif(Farms!$C$68:$C$104,E17,Farms!$G$68:$G$104) -> 13
A18: =IFERROR(__xludf.DUMMYFUNCTION("""COMPUTED_VALUE"""),45873.0) -> 45873 | B18: =IFERROR(__xludf.DUMMYFUNCTION("""COMPUTED_VALUE"""),"Airport") -> Airport | C18: =IFERROR(__xludf.DUMMYFUNCTION("""COMPUTED_VALUE"""),55960.0) -> 55960 | D18: =IFERROR(__xludf.DUMMYFUNCTION("""COMPUTED_VALUE"""),13.6) -> 13.6 | E18: =IFERROR(__xludf.DUMMYFUNCTION("""COMPUTED_VALUE"""),"Rye ") -> Rye | F18: =IFERROR(__xludf.DUMMYFUNCTION("""COMPUTED_VALUE"""),"H066697") -> H066697 | G18: =IFERROR(__xludf.DUMMYFUNCTION("""COMPUTED_VALUE"""),"HBT# 3127 4 Trk# 5 Julianne") -> HBT# 3127 4 Trk# 5 Julianne | H18: =IFERROR(__xludf.DUMMYFUNCTION("""COMPUTED_VALUE"""),0.1) -> 0.1 | I18: =if(H18>=1,H18-1,"0")/100 -> 0 | J18: =(((100-((D18-N18)*L18))*(C18))/M18)/100 -> 999.28571 | K18: =J18*(1-I18) -> 999.28571 | L18: =sumif(Farms!$C$68:$C$104,E18,Farms!$D$68:$D$104) -> 0 | M18: =sumif(Farms!$C$68:$C$104,E18,Farms!$F$68:$F$104) -> 56 | N18: =sumif(Farms!$C$68:$C$104,E18,Farms!$G$68:$G$104) -> 13
A19: =IFERROR(__xludf.DUMMYFUNCTION("""COMPUTED_VALUE"""),45876.0) -> 45876 | B19: =IFERROR(__xludf.DUMMYFUNCTION("""COMPUTED_VALUE"""),"Airport") -> Airport | C19: =IFERROR(__xludf.DUMMYFUNCTION("""COMPUTED_VALUE"""),57440.0) -> 57440 | D19: =IFERROR(__xludf.DUMMYFUNCTION("""COMPUTED_VALUE"""),13.1) -> 13.1 | E19: =IFERROR(__xludf.DUMMYFUNCTION("""COMPUTED_VALUE"""),"Rye ") -> Rye | F19: =IFERROR(__xludf.DUMMYFUNCTION("""COMPUTED_VALUE"""),"H066700") -> H066700 | G19: =IFERROR(__xludf.DUMMYFUNCTION("""COMPUTED_VALUE"""),"Blue Ticket 5075 truck 3 Bob ") -> Blue Ticket 5075 truck 3 Bob | H19: =IFERROR(__xludf.DUMMYFUNCTION("""COMPUTED_VALUE"""),0.4) -> 0.4 | I19: =if(H19>=1,H19-1,"0")/100 -> 0 | J19: =(((100-((D19-N19)*L19))*(C19))/M19)/100 -> 1025.7143 | K19: =J19*(1-I19) -> 1025.7143 | L19: =sumif(Farms!$C$68:$C$104,E19,Farms!$D$68:$D$104) -> 0 | M19: =sumif(Farms!$C$68:$C$104,E19,Farms!$F$68:$F$104) -> 56 | N19: =sumif(Farms!$C$68:$C$104,E19,Farms!$G$68:$G$104) -> 13 | O19: r
A20: =IFERROR(__xludf.DUMMYFUNCTION("""COMPUTED_VALUE"""),45876.0) -> 45876 | B20: =IFERROR(__xludf.DUMMYFUNCTION("""COMPUTED_VALUE"""),"Airport") -> Airport | C20: =IFERROR(__xludf.DUMMYFUNCTION("""COMPUTED_VALUE"""),53100.0) -> 53100 | D20: =IFERROR(__xludf.DUMMYFUNCTION("""COMPUTED_VALUE"""),12.6) -> 12.6 | E20: =IFERROR(__xludf.DUMMYFUNCTION("""COMPUTED_VALUE"""),"Rye ") -> Rye | F20: =IFERROR(__xludf.DUMMYFUNCTION("""COMPUTED_VALUE"""),"H066701") -> H066701 | G20: =IFERROR(__xludf.DUMMYFUNCTION("""COMPUTED_VALUE"""),"HBT# 4564 Airport Hipps Truck # 5 Bob Blue") -> HBT# 4564 Airport Hipps Truck # 5 Bob Blue | H20: =IFERROR(__xludf.DUMMYFUNCTION("""COMPUTED_VALUE"""),0.2) -> 0.2 | I20: =if(H20>=1,H20-1,"0")/100 -> 0 | J20: =(((100-((D20-N20)*L20))*(C20))/M20)/100 -> 948.21429 | K20: =J20*(1-I20) -> 948.21429 | L20: =sumif(Farms!$C$68:$C$104,E20,Farms!$D$68:$D$104) -> 0 | M20: =sumif(Farms!$C$68:$C$104,E20,Farms!$F$68:$F$104) -> 56 | N20: =sumif(Farms!$C$68:$C$104,E20,Farms!$G$68:$G$104) -> 13
A21: =IFERROR(__xludf.DUMMYFUNCTION("""COMPUTED_VALUE"""),45876.0) -> 45876 | B21: =IFERROR(__xludf.DUMMYFUNCTION("""COMPUTED_VALUE"""),"Airport") -> Airport | C21: =IFERROR(__xludf.DUMMYFUNCTION("""COMPUTED_VALUE"""),55020.0) -> 55020 | D21: =IFERROR(__xludf.DUMMYFUNCTION("""COMPUTED_VALUE"""),12.6) -> 12.6 | E21: =IFERROR(__xludf.DUMMYFUNCTION("""COMPUTED_VALUE"""),"Rye ") -> Rye | F21: =IFERROR(__xludf.DUMMYFUNCTION("""COMPUTED_VALUE"""),"H066702") -> H066702 | G21: =IFERROR(__xludf.DUMMYFUNCTION("""COMPUTED_VALUE"""),"HBT#3128 Airport Hipps Truck # 5 Bob") -> HBT#3128 Airport Hipps Truck # 5 Bob | H21: =IFERROR(__xludf.DUMMYFUNCTION("""COMPUTED_VALUE"""),0.2) -> 0.2 | I21: =if(H21>=1,H21-1,"0")/100 -> 0 | J21: =(((100-((D21-N21)*L21))*(C21))/M21)/100 -> 982.5 | K21: =J21*(1-I21) -> 982.5 | L21: =sumif(Farms!$C$68:$C$104,E21,Farms!$D$68:$D$104) -> 0 | M21: =sumif(Farms!$C$68:$C$104,E21,Farms!$F$68:$F$104) -> 56 | N21: =sumif(Farms!$C$68:$C$104,E21,Farms!$G$68:$G$104) -> 13
A22: =IFERROR(__xludf.DUMMYFUNCTION("""COMPUTED_VALUE"""),45877.0) -> 45877 | B22: =IFERROR(__xludf.DUMMYFUNCTION("""COMPUTED_VALUE"""),"Airport") -> Airport | C22: =IFERROR(__xludf.DUMMYFUNCTION("""COMPUTED_VALUE"""),57260.0) -> 57260 | D22: =IFERROR(__xludf.DUMMYFUNCTION("""COMPUTED_VALUE"""),13.7) -> 13.7 | E22: =IFERROR(__xludf.DUMMYFUNCTION("""COMPUTED_VALUE"""),"Rye ") -> Rye | F22: =IFERROR(__xludf.DUMMYFUNCTION("""COMPUTED_VALUE"""),"H066703") -> H066703 | G22: =IFERROR(__xludf.DUMMYFUNCTION("""COMPUTED_VALUE"""),"Hipps and Jrs HBT # 5076 #3 Bob") -> Hipps and Jrs HBT # 5076 #3 Bob | H22: =IFERROR(__xludf.DUMMYFUNCTION("""COMPUTED_VALUE"""),0.09) -> 0.09 | I22: =if(H22>=1,H22-1,"0")/100 -> 0 | J22: =(((100-((D22-N22)*L22))*(C22))/M22)/100 -> 1022.5 | K22: =J22*(1-I22) -> 1022.5 | L22: =sumif(Farms!$C$68:$C$104,E22,Farms!$D$68:$D$104) -> 0 | M22: =sumif(Farms!$C$68:$C$104,E22,Farms!$F$68:$F$104) -> 56 | N22: =sumif(Farms!$C$68:$C$104,E22,Farms!$G$68:$G$104) -> 13
A23: =IFERROR(__xludf.DUMMYFUNCTION("""COMPUTED_VALUE"""),45877.0) -> 45877 | B23: =IFERROR(__xludf.DUMMYFUNCTION("""COMPUTED_VALUE"""),"Airport") -> Airport | C23: =IFERROR(__xludf.DUMMYFUNCTION("""COMPUTED_VALUE"""),58880.0) -> 58880 | D23: =IFERROR(__xludf.DUMMYFUNCTION("""COMPUTED_VALUE"""),12.2) -> 12.2 | E23: =IFERROR(__xludf.DUMMYFUNCTION("""COMPUTED_VALUE"""),"Rye ") -> Rye | F23: =IFERROR(__xludf.DUMMYFUNCTION("""COMPUTED_VALUE"""),"H066704") -> H066704 | G23: =IFERROR(__xludf.DUMMYFUNCTION("""COMPUTED_VALUE"""),"Hipps Juniors HBT# 5518 Bob #2") -> Hipps Juniors HBT# 5518 Bob #2 | H23: =IFERROR(__xludf.DUMMYFUNCTION("""COMPUTED_VALUE"""),0.5) -> 0.5 | I23: =if(H23>=1,H23-1,"0")/100 -> 0 | J23: =(((100-((D23-N23)*L23))*(C23))/M23)/100 -> 1051.4286 | K23: =J23*(1-I23) -> 1051.4286 | L23: =sumif(Farms!$C$68:$C$104,E23,Farms!$D$68:$D$104) -> 0 | M23: =sumif(Farms!$C$68:$C$104,E23,Farms!$F$68:$F$104) -> 56 | N23: =sumif(Farms!$C$68:$C$104,E23,Farms!$G$68:$G$104) -> 13
A24: =IFERROR(__xludf.DUMMYFUNCTION("""COMPUTED_VALUE"""),45877.0) -> 45877 | B24: =IFERROR(__xludf.DUMMYFUNCTION("""COMPUTED_VALUE"""),"Airport - Knilans") -> Airport - Knilans | C24: =IFERROR(__xludf.DUMMYFUNCTION("""COMPUTED_VALUE"""),16980.0) -> 16980 | D24: =IFERROR(__xludf.DUMMYFUNCTION("""COMPUTED_VALUE"""),12.7) -> 12.7 | E24: =IFERROR(__xludf.DUMMYFUNCTION("""COMPUTED_VALUE"""),"Rye ") -> Rye | F24: =IFERROR(__xludf.DUMMYFUNCTION("""COMPUTED_VALUE"""),"H066705") -> H066705 | G24: =IFERROR(__xludf.DUMMYFUNCTION("""COMPUTED_VALUE"""),"HBT# 4565 Bob # 63 trailer 4 last load of Rye ") -> HBT# 4565 Bob # 63 trailer 4 last load of Rye | H24: =IFERROR(__xludf.DUMMYFUNCTION("""COMPUTED_VALUE"""),0.2) -> 0.2 | I24: =if(H24>=1,H24-1,"0")/100 -> 0 | J24: =(((100-((D24-N24)*L24))*(C24))/M24)/100 -> 303.21429 | K24: =J24*(1-I24) -> 303.21429 | L24: =sumif(Farms!$C$68:$C$104,E24,Farms!$D$68:$D$104) -> 0 | M24: =sumif(Farms!$C$68:$C$104,E24,Farms!$F$68:$F$104) -> 56 | N24: =sumif(Farms!$C$68:$C$104,E24,Farms!$G$68:$G$104) -> 13
A25: =IFERROR(__xludf.DUMMYFUNCTION("""COMPUTED_VALUE"""),45936.0) -> 45936 | B25: =IFERROR(__xludf.DUMMYFUNCTION("""COMPUTED_VALUE"""),"bakke") -> bakke | C25: =IFERROR(__xludf.DUMMYFUNCTION("""COMPUTED_VALUE"""),55980.0) -> 55980 | D25: =IFERROR(__xludf.DUMMYFUNCTION("""COMPUTED_VALUE"""),15.4) -> 15.4 | E25: =IFERROR(__xludf.DUMMYFUNCTION("""COMPUTED_VALUE"""),"Non-GMO Yellow Corn") -> Non-GMO Yellow Corn | F25: =IFERROR(__xludf.DUMMYFUNCTION("""COMPUTED_VALUE"""),"0548919") -> 0548919 | G25: =IFERROR(__xludf.DUMMYFUNCTION("""COMPUTED_VALUE"""),"HBT# 5859 Bob Trk# 3") -> HBT# 5859 Bob Trk# 3 | I25: =if(H25>=1,H25-1,"0")/100 -> 0 | J25: =(((100-((D25-N25)*L25))*(C25))/M25)/100 -> 993.645 | K25: =J25*(1-I25) -> 993.645 | L25: =sumif(Farms!$C$68:$C$104,E25,Farms!$D$68:$D$104) -> 1.5 | M25: =sumif(Farms!$C$68:$C$104,E25,Farms!$F$68:$F$104) -> 56 | N25: =sumif(Farms!$C$68:$C$104,E25,Farms!$G$68:$G$104) -> 15
A26: =IFERROR(__xludf.DUMMYFUNCTION("""COMPUTED_VALUE"""),45936.0) -> 45936 | B26: =IFERROR(__xludf.DUMMYFUNCTION("""COMPUTED_VALUE"""),"bakke") -> bakke | C26: =IFERROR(__xludf.DUMMYFUNCTION("""COMPUTED_VALUE"""),54920.0) -> 54920 | D26: =IFERROR(__xludf.DUMMYFUNCTION("""COMPUTED_VALUE"""),15.8) -> 15.8 | E26: =IFERROR(__xludf.DUMMYFUNCTION("""COMPUTED_VALUE"""),"Non-GMO Yellow Corn") -> Non-GMO Yellow Corn | F26: =IFERROR(__xludf.DUMMYFUNCTION("""COMPUTED_VALUE"""),"0548922") -> 0548922 | G26: =IFERROR(__xludf.DUMMYFUNCTION("""COMPUTED_VALUE"""),"HBT#5534 Tanner Trk# 2") -> HBT#5534 Tanner Trk# 2 | I26: =if(H26>=1,H26-1,"0")/100 -> 0 | J26: =(((100-((D26-N26)*L26))*(C26))/M26)/100 -> 968.94571 | K26: =J26*(1-I26) -> 968.94571 | L26: =sumif(Farms!$C$68:$C$104,E26,Farms!$D$68:$D$104) -> 1.5 | M26: =sumif(Farms!$C$68:$C$104,E26,Farms!$F$68:$F$104) -> 56 | N26: =sumif(Farms!$C$68:$C$104,E26,Farms!$G$68:$G$104) -> 15
A27: =IFERROR(__xludf.DUMMYFUNCTION("""COMPUTED_VALUE"""),45936.0) -> 45936 | B27: =IFERROR(__xludf.DUMMYFUNCTION("""COMPUTED_VALUE"""),"bakke") -> bakke | C27: =IFERROR(__xludf.DUMMYFUNCTION("""COMPUTED_VALUE"""),57040.0) -> 57040 | D27: =IFERROR(__xludf.DUMMYFUNCTION("""COMPUTED_VALUE"""),15.4) -> 15.4 | E27: =IFERROR(__xludf.DUMMYFUNCTION("""COMPUTED_VALUE"""),"Non-GMO Yellow Corn") -> Non-GMO Yellow Corn | F27: =IFERROR(__xludf.DUMMYFUNCTION("""COMPUTED_VALUE"""),"0548924") -> 0548924 | G27: =IFERROR(__xludf.DUMMYFUNCTION("""COMPUTED_VALUE"""),"HBT#4575 Jack Trk# 63 ") -> HBT#4575 Jack Trk# 63 | I27: =if(H27>=1,H27-1,"0")/100 -> 0 | J27: =(((100-((D27-N27)*L27))*(C27))/M27)/100 -> 1012.46 | K27: =J27*(1-I27) -> 1012.46 | L27: =sumif(Farms!$C$68:$C$104,E27,Farms!$D$68:$D$104) -> 1.5 | M27: =sumif(Farms!$C$68:$C$104,E27,Farms!$F$68:$F$104) -> 56 | N27: =sumif(Farms!$C$68:$C$104,E27,Farms!$G$68:$G$104) -> 15
A28: =IFERROR(__xludf.DUMMYFUNCTION("""COMPUTED_VALUE"""),45936.0) -> 45936 | B28: =IFERROR(__xludf.DUMMYFUNCTION("""COMPUTED_VALUE"""),"bakke") -> bakke | C28: =IFERROR(__xludf.DUMMYFUNCTION("""COMPUTED_VALUE"""),55040.0) -> 55040 | D28: =IFERROR(__xludf.DUMMYFUNCTION("""COMPUTED_VALUE"""),15.5) -> 15.5 | E28: =IFERROR(__xludf.DUMMYFUNCTION("""COMPUTED_VALUE"""),"Non-GMO Yellow Corn") -> Non-GMO Yellow Corn | F28: =IFERROR(__xludf.DUMMYFUNCTION("""COMPUTED_VALUE"""),"0548928") -> 0548928 | G28: =IFERROR(__xludf.DUMMYFUNCTION("""COMPUTED_VALUE"""),"HBT#5754 WDH Trk# 4") -> HBT#5754 WDH Trk# 4 | I28: =if(H28>=1,H28-1,"0")/100 -> 0 | J28: =(((100-((D28-N28)*L28))*(C28))/M28)/100 -> 975.48571 | K28: =J28*(1-I28) -> 975.48571 | L28: =sumif(Farms!$C$68:$C$104,E28,Farms!$D$68:$D$104) -> 1.5 | M28: =sumif(Farms!$C$68:$C$104,E28,Farms!$F$68:$F$104) -> 56 | N28: =sumif(Farms!$C$68:$C$104,E28,Farms!$G$68:$G$104) -> 15
A29: =IFERROR(__xludf.DUMMYFUNCTION("""COMPUTED_VALUE"""),45936.0) -> 45936 | B29: =IFERROR(__xludf.DUMMYFUNCTION("""COMPUTED_VALUE"""),"bakke") -> bakke | C29: =IFERROR(__xludf.DUMMYFUNCTION("""COMPUTED_VALUE"""),57620.0) -> 57620 | D29: =IFERROR(__xludf.DUMMYFUNCTION("""COMPUTED_VALUE"""),15.9) -> 15.9 | E29: =IFERROR(__xludf.DUMMYFUNCTION("""COMPUTED_VALUE"""),"Non-GMO Yellow Corn") -> Non-GMO Yellow Corn | F29: =IFERROR(__xludf.DUMMYFUNCTION("""COMPUTED_VALUE"""),"0548931") -> 0548931 | G29: =IFERROR(__xludf.DUMMYFUNCTION("""COMPUTED_VALUE"""),"HBT#5201 JB Trk# 5") -> HBT#5201 JB Trk# 5 | I29: =if(H29>=1,H29-1,"0")/100 -> 0 | J29: =(((100-((D29-N29)*L29))*(C29))/M29)/100 -> 1015.038 | K29: =J29*(1-I29) -> 1015.038 | L29: =sumif(Farms!$C$68:$C$104,E29,Farms!$D$68:$D$104) -> 1.5 | M29: =sumif(Farms!$C$68:$C$104,E29,Farms!$F$68:$F$104) -> 56 | N29: =sumif(Farms!$C$68:$C$104,E29,Farms!$G$68:$G$104) -> 15
A30: =IFERROR(__xludf.DUMMYFUNCTION("""COMPUTED_VALUE"""),45936.0) -> 45936 | B30: =IFERROR(__xludf.DUMMYFUNCTION("""COMPUTED_VALUE"""),"bakke") -> bakke | C30: =IFERROR(__xludf.DUMMYFUNCTION("""COMPUTED_VALUE"""),55920.0) -> 55920 | D30: =IFERROR(__xludf.DUMMYFUNCTION("""COMPUTED_VALUE"""),15.7) -> 15.7 | E30: =IFERROR(__xludf.DUMMYFUNCTION("""COMPUTED_VALUE"""),"Non-GMO Yellow Corn") -> Non-GMO Yellow Corn | F30: =IFERROR(__xludf.DUMMYFUNCTION("""COMPUTED_VALUE"""),"0548932") -> 0548932 | G30: =IFERROR(__xludf.DUMMYFUNCTION("""COMPUTED_VALUE"""),"HBT#5860 Bob Trk# 3 Last Load") -> HBT#5860 Bob Trk# 3 Last Load | I30: 0 | J30: =(((100-((D30-N30)*L30))*(C30))/M30)/100 -> 958.12929 | K30: =J30*(1-I30) -> 958.12929 | L30: =sumif(Farms!$C$68:$C$104,E30,Farms!$D$68:$D$104) -> 1.5 | M30: 56 | N30: 13 | O30: r
A31: =IFERROR(__xludf.DUMMYFUNCTION("""COMPUTED_VALUE"""),45853.0) -> 45853 | B31: =IFERROR(__xludf.DUMMYFUNCTION("""COMPUTED_VALUE"""),"blue ") -> blue | C31: =IFERROR(__xludf.DUMMYFUNCTION("""COMPUTED_VALUE"""),56760.0) -> 56760 | E31: =IFERROR(__xludf.DUMMYFUNCTION("""COMPUTED_VALUE"""),"Hybrid Rye") -> Hybrid Rye | F31: =IFERROR(__xludf.DUMMYFUNCTION("""COMPUTED_VALUE"""),"00130") -> 00130 | G31: =IFERROR(__xludf.DUMMYFUNCTION("""COMPUTED_VALUE"""),"HBT#5070 Bob Trk # 3 1st load") -> HBT#5070 Bob Trk # 3 1st load | I31: =if(H31>=1,H31-1,"0")/100 -> 0 | J31: =(((100-((D31-N31)*L31))*(C31))/M31)/100 -> 1013.5714 | K31: =J31*(1-I31) -> 1013.5714 | L31: =sumif(Farms!$C$68:$C$104,E31,Farms!$D$68:$D$104) -> 0 | M31: 56 | N31: 13
A32: =IFERROR(__xludf.DUMMYFUNCTION("""COMPUTED_VALUE"""),45853.0) -> 45853 | B32: =IFERROR(__xludf.DUMMYFUNCTION("""COMPUTED_VALUE"""),"blue ") -> blue | C32: =IFERROR(__xludf.DUMMYFUNCTION("""COMPUTED_VALUE"""),58200.0) -> 58200 | E32: =IFERROR(__xludf.DUMMYFUNCTION("""COMPUTED_VALUE"""),"Hybrid Rye") -> Hybrid Rye | F32: =IFERROR(__xludf.DUMMYFUNCTION("""COMPUTED_VALUE"""),"00131") -> 00131 | G32: =IFERROR(__xludf.DUMMYFUNCTION("""COMPUTED_VALUE"""),"HBT# 5506 Bob Trk 2") -> HBT# 5506 Bob Trk 2 | I32: =if(H32>=1,H32-1,"0")/100 -> 0 | J32: =(((100-((D32-N32)*L32))*(C32))/M32)/100 -> 1039.2857 | K32: =J32*(1-I32) -> 1039.2857 | L32: =sumif(Farms!$C$68:$C$104,E32,Farms!$D$68:$D$104) -> 0 | M32: 56 | N32: 13
A33: =IFERROR(__xludf.DUMMYFUNCTION("""COMPUTED_VALUE"""),45853.0) -> 45853 | B33: =IFERROR(__xludf.DUMMYFUNCTION("""COMPUTED_VALUE"""),"blue ") -> blue | C33: =IFERROR(__xludf.DUMMYFUNCTION("""COMPUTED_VALUE"""),56180.0) -> 56180 | E33: =IFERROR(__xludf.DUMMYFUNCTION("""COMPUTED_VALUE"""),"Hybrid Rye") -> Hybrid Rye | F33: =IFERROR(__xludf.DUMMYFUNCTION("""COMPUTED_VALUE"""),"00136") -> 00136 | G33: =IFERROR(__xludf.DUMMYFUNCTION("""COMPUTED_VALUE"""),"HBT#3117 Gary Trk 5") -> HBT#3117 Gary Trk 5 | I33: =if(H33>=1,H33-1,"0")/100 -> 0 | J33: =(((100-((D33-N33)*L33))*(C33))/M33)/100 -> 1003.2143 | K33: =J33*(1-I33) -> 1003.2143 | L33: =sumif(Farms!$C$68:$C$104,E33,Farms!$D$68:$D$104) -> 0 | M33: 56 | N33: 13
A34: =IFERROR(__xludf.DUMMYFUNCTION("""COMPUTED_VALUE"""),45853.0) -> 45853 | B34: =IFERROR(__xludf.DUMMYFUNCTION("""COMPUTED_VALUE"""),"blue ") -> blue | C34: =IFERROR(__xludf.DUMMYFUNCTION("""COMPUTED_VALUE"""),57240.0) -> 57240 | E34: =IFERROR(__xludf.DUMMYFUNCTION("""COMPUTED_VALUE"""),"Hybrid Rye") -> Hybrid Rye | F34: =IFERROR(__xludf.DUMMYFUNCTION("""COMPUTED_VALUE"""),"00137") -> 00137 | G34: =IFERROR(__xludf.DUMMYFUNCTION("""COMPUTED_VALUE"""),"HBT# 5071 Bob Trk # 3") -> HBT# 5071 Bob Trk # 3 | I34: =if(H34>=1,H34-1,"0")/100 -> 0 | J34: =(((100-((D34-N34)*L34))*(C34))/M34)/100 -> 1022.1429 | K34: =J34*(1-I34) -> 1022.1429 | L34: =sumif(Farms!$C$68:$C$104,E34,Farms!$D$68:$D$104) -> 0 | M34: 56 | N34: 13
A35: =IFERROR(__xludf.DUMMYFUNCTION("""COMPUTED_VALUE"""),45853.0) -> 45853 | B35: =IFERROR(__xludf.DUMMYFUNCTION("""COMPUTED_VALUE"""),"blue ") -> blue | C35: =IFERROR(__xludf.DUMMYFUNCTION("""COMPUTED_VALUE"""),56520.0) -> 56520 | E35: =IFERROR(__xludf.DUMMYFUNCTION("""COMPUTED_VALUE"""),"Hybrid Rye") -> Hybrid Rye | F35: =IFERROR(__xludf.DUMMYFUNCTION("""COMPUTED_VALUE"""),"00140") -> 00140 | G35: =IFERROR(__xludf.DUMMYFUNCTION("""COMPUTED_VALUE"""),"HBT# 5507 Tanner Trk # 2") -> HBT# 5507 Tanner Trk # 2 | I35: =if(H35>=1,H35-1,"0")/100 -> 0 | J35: =(((100-((D35-N35)*L35))*(C35))/M35)/100 -> 1009.2857 | K35: =J35*(1-I35) -> 1009.2857 | L35: =sumif(Farms!$C$68:$C$104,E35,Farms!$D$68:$D$104) -> 0 | M35: 56 | N35: 13
A36: =IFERROR(__xludf.DUMMYFUNCTION("""COMPUTED_VALUE"""),45853.0) -> 45853 | B36: =IFERROR(__xludf.DUMMYFUNCTION("""COMPUTED_VALUE"""),"blue ") -> blue | C36: =IFERROR(__xludf.DUMMYFUNCTION("""COMPUTED_VALUE"""),53880.0) -> 53880 | E36: =IFERROR(__xludf.DUMMYFUNCTION("""COMPUTED_VALUE"""),"Hybrid Rye") -> Hybrid Rye | F36: =IFERROR(__xludf.DUMMYFUNCTION("""COMPUTED_VALUE"""),"00141") -> 00141 | G36: =IFERROR(__xludf.DUMMYFUNCTION("""COMPUTED_VALUE"""),"HBT# 4553 WDH Trk # 63") -> HBT# 4553 WDH Trk # 63 | I36: =if(H36>=1,H36-1,"0")/100 -> 0 | J36: =(((100-((D36-N36)*L36))*(C36))/M36)/100 -> 962.14286 | K36: =J36*(1-I36) -> 962.14286 | L36: =sumif(Farms!$C$68:$C$104,E36,Farms!$D$68:$D$104) -> 0 | M36: 56 | N36: 13
A37: =IFERROR(__xludf.DUMMYFUNCTION("""COMPUTED_VALUE"""),45853.0) -> 45853 | B37: =IFERROR(__xludf.DUMMYFUNCTION("""COMPUTED_VALUE"""),"blue ") -> blue | C37: =IFERROR(__xludf.DUMMYFUNCTION("""COMPUTED_VALUE"""),56260.0) -> 56260 | E37: =IFERROR(__xludf.DUMMYFUNCTION("""COMPUTED_VALUE"""),"Hybrid Rye") -> Hybrid Rye | F37: =IFERROR(__xludf.DUMMYFUNCTION("""COMPUTED_VALUE"""),"00143") -> 00143 | G37: =IFERROR(__xludf.DUMMYFUNCTION("""COMPUTED_VALUE"""),"HBT# 3118 Gary Trk # 5") -> HBT# 3118 Gary Trk # 5 | I37: =if(H37>=1,H37-1,"0")/100 -> 0 | J37: =(((100-((D37-N37)*L37))*(C37))/M37)/100 -> 1004.6429 | K37: =J37*(1-I37) -> 1004.6429 | L37: =sumif(Farms!$C$68:$C$104,E37,Farms!$D$68:$D$104) -> 0 | M37: =sumif(Farms!$C$68:$C$104,E37,Farms!$F$68:$F$104) -> 56 | N37: 13
A38: =IFERROR(__xludf.DUMMYFUNCTION("""COMPUTED_VALUE"""),45853.0) -> 45853 | B38: =IFERROR(__xludf.DUMMYFUNCTION("""COMPUTED_VALUE"""),"blue ") -> blue | C38: =IFERROR(__xludf.DUMMYFUNCTION("""COMPUTED_VALUE"""),55540.0) -> 55540 | E38: =IFERROR(__xludf.DUMMYFUNCTION("""COMPUTED_VALUE"""),"Hybrid Rye") -> Hybrid Rye | F38: =IFERROR(__xludf.DUMMYFUNCTION("""COMPUTED_VALUE"""),"00144") -> 00144 | G38: =IFERROR(__xludf.DUMMYFUNCTION("""COMPUTED_VALUE"""),"HBT# 5072 Bob Trk # 3") -> HBT# 5072 Bob Trk # 3 | I38: =if(H38>=1,H38-1,"0")/100 -> 0 | J38: =(((100-((D38-N38)*L38))*(C38))/M38)/100 -> 991.78571 | K38: =J38*(1-I38) -> 991.78571 | L38: =sumif(Farms!$C$68:$C$104,E38,Farms!$D$68:$D$104) -> 0 | M38: 56 | N38: 13
A39: =IFERROR(__xludf.DUMMYFUNCTION("""COMPUTED_VALUE"""),45853.0) -> 45853 | B39: =IFERROR(__xludf.DUMMYFUNCTION("""COMPUTED_VALUE"""),"blue ") -> blue | C39: =IFERROR(__xludf.DUMMYFUNCTION("""COMPUTED_VALUE"""),55620.0) -> 55620 | E39: =IFERROR(__xludf.DUMMYFUNCTION("""COMPUTED_VALUE"""),"Hybrid Rye") -> Hybrid Rye | F39: =IFERROR(__xludf.DUMMYFUNCTION("""COMPUTED_VALUE"""),"00145") -> 00145 | G39: =IFERROR(__xludf.DUMMYFUNCTION("""COMPUTED_VALUE"""),"HBT# 5508 Tanner Trk # 2") -> HBT# 5508 Tanner Trk # 2 | I39: =if(H39>=1,H39-1,"0")/100 -> 0 | J39: =(((100-((D39-N39)*L39))*(C39))/M39)/100 -> 993.21429 | K39: =J39*(1-I39) -> 993.21429 | L39: =sumif(Farms!$C$68:$C$104,E39,Farms!$D$68:$D$104) -> 0 | M39: =sumif(Farms!$C$68:$C$104,E39,Farms!$F$68:$F$104) -> 56 | N39: =sumif(Farms!$C$68:$C$104,E39,Farms!$G$68:$G$104) -> 13
A40: =IFERROR(__xludf.DUMMYFUNCTION("""COMPUTED_VALUE"""),45854.0) -> 45854 | B40: =IFERROR(__xludf.DUMMYFUNCTION("""COMPUTED_VALUE"""),"blue ") -> blue | C40: =IFERROR(__xludf.DUMMYFUNCTION("""COMPUTED_VALUE"""),55300.0) -> 55300 | E40: =IFERROR(__xludf.DUMMYFUNCTION("""COMPUTED_VALUE"""),"Hybrid Rye") -> Hybrid Rye | F40: =IFERROR(__xludf.DUMMYFUNCTION("""COMPUTED_VALUE"""),"00146") -> 00146 | G40: =IFERROR(__xludf.DUMMYFUNCTION("""COMPUTED_VALUE"""),"HBT# 4380 Gary Trk # 4") -> HBT# 4380 Gary Trk # 4 | I40: =if(H40>=1,H40-1,"0")/100 -> 0 | J40: =(((100-((D40-N40)*L40))*(C40))/M40)/100 -> 987.5 | K40: =J40*(1-I40) -> 987.5 | L40: =sumif(Farms!$C$68:$C$104,E40,Farms!$D$68:$D$104) -> 0 | M40: =sumif(Farms!$C$68:$C$104,E40,Farms!$F$68:$F$104) -> 56 | N40: =sumif(Farms!$C$68:$C$104,E40,Farms!$G$68:$G$104) -> 13
...

Sheet Data Lookup
B2: Ticket Data Lookup Form
D6: Date: | F6: 44468
D8: Farm: | F8: OMNI
D10: Net Weight:
D12: Moisture:
D14: Crop
D16: Ticket Number | F16: H053910
D18: Notes: | F18: =IFERROR(__xludf.DUMMYFUNCTION("IFERROR(FILTER(Data!G:G,Data!F:F=F16))"),"")

Sheet Data
A1: Date | B1: FARM | C1: NET WEIGHT | D1: MOISTURE | E1: CROP | F1: TICKET NO. | G1: NOTES | H1: FM
A2: 45860 | B2: Airport | C2: 55480 | D2: 12.9 | E2: Rye | F2: H066666 | G2: HBT# 5652 WR Trk# 41 | H2: 0.1
A3: 45860 | B3: Airport | C3: 42780 | D3: 13.5 | E3: Rye | F3: H066668 | G3: HBT# 3122 Bob Trk# 5 | H3: 0.2
A4: 45866 | B4: Airport | C4: 56480 | D4: 12.5 | E4: Rye | F4: H066671 | G4: HBT# 4558 Bob Trk# 63 | H4: 0.1
A5: 45866 | B5: Airport | C5: 54480 | D5: 11.9 | E5: Rye | F5: H066672 | G5: HBT# 5653 WR Trk# 41 | H5: 0.2
A6: 45866 | B6: Airport | C6: 57020 | D6: 12 | E6: Rye | F6: H066673 | G6: HBT# 3124 Bob Trk# 5 | H6: 0.19
A7: 45868 | B7: Airport | C7: 55540 | D7: 13 | E7: Rye | F7: H066675 | G7: HBT# 3125 Julianne Trk# 5 | H7: 0.1
A8: 45868 | B8: Airport | C8: 55440 | D8: 13.1 | E8: Rye | F8: H066676 | G8: HBT# 5515 WR Trk# 5 | H8: 0.2
A9: 45868 | B9: Airport | C9: 51340 | D9: 13.8 | E9: Rye | F9: H066677 | G9: HBT# 4559 Gary Trk#63 | H9: 0.1
A10: 45868 | B10: Airport | C10: 53960 | D10: 13.6 | E10: Rye | F10: H066679 | G10: HBT# 5654 Gary Trk# 41 | H10: 0.1
A11: 45873 | B11: Airport | C11: 59780 | D11: 13 | E11: Rye | F11: H066689 | G11: HBT# 3126 Julianne Trk# 5 | H11: 0.2
A12: 45873 | B12: Airport | C12: 48520 | D12: 12.3 | E12: Rye | F12: H066690 | G12: HBT# 4560 Bob Trk# 63 | H12: 0.1
A13: 45873 | B13: Airport | C13: 57760 | D13: 12.9 | E13: Rye | F13: H066691 | G13: HBT# 5516 Tanner Trk# 2 | H13: 0.2
... A24: 45877 | B24: Airport - Knilans | C24: 16980 | D24: 12.7 | E24: Rye | F24: H066705 | G24: HBT# 4565 Bob # 63 trailer 4 last load of Rye | H24: 0.2
A25: 45936 | B25: bakke | C25: 55980 | D25: 15.4 | E25: Non-GMO Yellow Corn | F25: 0548919 | G25: HBT# 5859 Bob Trk# 3
A26: 45936 | B26: bakke | C26: 54920 | D26: 15.8 | E26: Non-GMO Yellow Corn | F26: 0548922 | G26: HBT#5534 Tanner Trk# 2
A27: 45936 | B27: bakke | C27: 57040 | D27: 15.4 | E27: Non-GMO Yellow Corn | F27: 0548924 | G27: HBT#4575 Jack Trk# 63
A28: 45936 | B28: bakke | C28: 55040 | D28: 15.5 | E28: Non-GMO Yellow Corn | F28: 0548928 | G28: HBT#5754 WDH Trk# 4
A29: 45936 | B29: bakke | C29: 57620 | D29: 15.9 | E29: Non-GMO Yellow Corn | F29: 0548931 | G29: HBT#5201 JB Trk# 5
A30: 45936 | B30: bakke | C30: 55920 | D30: 15.7 | E30: Non-GMO Yellow Corn | F30: 0548932 | G30: HBT#5860 Bob Trk# 3 Last Load
A31: 45853 | B31: blue | C31: 56760 | E31: Hybrid Rye | F31: 00130 | G31: HBT#5070 Bob Trk # 3 1st load
A32: 45853 | B32: blue | C32: 58200 | E32: Hybrid Rye | F32: 00131 | G32: HBT# 5506 Bob Trk 2
A33: 45853 | B33: blue | C33: 56180 | E33: Hybrid Rye | F33: 00136 | G33: HBT#3117 Gary Trk 5
A34: 45853 | B34: blue | C34: 57240 | E34: Hybrid Rye | F34: 00137 | G34: HBT# 5071 Bob Trk # 3
A35: 45853 | B35: blue | C35: 56520 | E35: Hybrid Rye | F35: 00140 | G35: HBT# 5507 Tanner Trk # 2
A36: 45853 | B36: blue | C36: 53880 | E36: Hybrid Rye | F36: 00141 | G36: HBT# 4553 WDH Trk # 63
A37: 45853 | B37: blue | C37: 56260 | E37: Hybrid Rye | F37: 00143 | G37: HBT# 3118 Gary Trk # 5
A38: 45853 | B38: blue | C38: 55540 | E38: Hybrid Rye | F38: 00144 | G38: HBT# 5072 Bob Trk # 3
A39: 45853 | B39: blue | C39: 55620 | E39: Hybrid Rye | F39: 00145 | G39: HBT# 5508 Tanner Trk # 2
A40: 45854 | B40: blue | C40: 55300 | E40: Hybrid Rye | F40: 00146 | G40: HBT# 4380 Gary Trk # 4
A41: 45854 | B41: blue | C41: 54700 | E41: Hybrid Rye | F41: 00150 | G41: HBT# 5701 Bob Trk # 5
A42: 45855 | B42: blue | C42: 53220 | E42: Hybrid Rye | F42: 00152 | G42: HBT# 4554 Bob Trk# 5
... A45: 45856 | B45: blue | C45: 55680 | E45: Hybrid Rye | F45: 00165 | G45: HBT# 3119 Bob Trk# 5 Last Load
A46: 45860 | B46: blue crop #2 | C46: 20340 | D46: 13.3 | E46: Rye | F46: H066664 | G46: HBT# 1601 JB Trk Tandem - Clean out
A47: 45907 | B47: buchanon crop #1 | C47: 99625 | E47: Lima Beans | F47: 531-041005 - 9,16 | G47: Seneca
A48: 45930 | B48: buchanon crop #2 | C48: 32432 | D48: 13.2 | E48: Enlist Soybeans | F48: M038432 | G48: Split Load HBT#5091 Bob Trk# 3 | H48: 0.23
A49: 45918 | B49: carrol | C49: 50720 | E49: 262 OR Seed beans | F49: 262 | G49: GR01 Ken Trucked
A50: 45918 | B50: carrol | C50: 29040 | E50: 262 OR Seed beans | F50: 67963 | G50: Scoular
A51: 45918 | B51: carrol | C51: 52060 | E51: 262 OR Seed beans | F51: 76806 | G51: Scoular
A52: 45918 | B52: carrol | C52: 56480 | E52: 262 OR Seed beans | F52: 0263 | G52: HBT# 3132 WDH Trk # 5
...
